Workbook

Sheet LISEZ-MOI
A1: Helium, coût par mission et plan de charge MVP, V1
A3: Objet | B3: Réponse chiffrée à la demande de cadrage Finance → Produit/Technique (2 FINANCE/PREVISIONS/2026 1027 Demande de cadrage Produit Technique) : coût unitaire par mission, coût variable par abonné, protections contre les dérives, plan de charge et budget MVP.
A4: Statut | B4: Document de travail préparé par l'assistant IA Direction à la demande du CEO (Malik), le 28/10/2026. Rien n'est mesuré : tous les volumes de jetons, taux de réussite et minutes sont des hypothèses d'ingénierie, étiquetées comme telles. Seuls les prix unitaires marqués « Tarif public » sont sourcés (URL et date dans l'onglet Tarifs).
A5: Légende | B5: Texte bleu = entrée modifiable (hypothèse). Fond jaune = levier clé. Texte noir = formule. Texte vert = lien vers un autre onglet. Fond vert pâle (Tarifs) = prix public sourcé.
A6: Onglets | B6: Tarifs (prix unitaires, taux de change, coût du support) · Missions (paramètres et coût par exécution, par mission) · Synthèse (coût variable par abonné et par offre, comparaison avec l'hypothèse Finance H03 et avec le modèle 36 mois) · Sensibilité (variations linéaires des composantes) · Protections (plafonds par offre et coût au plafond) · Plan de charge (jours par profil, budget MVP, comparaison avec les 77 050 € du Business plan Lean V1) · Tableau commun (le format demandé par Finance).
A7: Mécanique | B7: Coût d'une exécution = facteur de reprises × [appels petit modèle × (entrée non cachée × prix + entrée cachée × prix caché + sortie × prix) + appels moyen × idem, dont une part escaladée vers le modèle frontière] + recherches + lieux + lectures de page + minutes de navigateur piloté + minutes de support humain espérées. Prix en dollars convertis en euros au taux de l'onglet Tarifs. Coût mensuel par abonné = somme des fréquences × coût par exécution, pondérée par offre.
A8: Ce que mesure le pilote | B8: Pour les missions 1 et 5 d'abord, puis 3 et 4 : jetons réels par étape, nombre d'étapes, reprises, taux de réussite sans correction, minutes de support. Chaque mesure remplace une cellule bleue de l'onglet Missions. Le classeur est conçu pour que Finance n'ait qu'à substituer.
A9: Contrôles | B9: Recalcul complet sous LibreOffice, zéro erreur ; cohérence du nombre d'exécutions par offre avec les 20 / 60 / 90 missions par mois du modèle financier 36 mois ; coût moyen par mission comparé à l'hypothèse de 0,18 € (central) et 0,30 € (prudent) de ce modèle.
A10: Liens | B10: Modèle financier 36 mois (Finance/Helium_Modele_financier_36m_V1.xlsx) · Réponse au cadrage (Technique/2026 1028 Reponse au cadrage Produit Technique V1.docx) · Contribution marketing au cadrage MVP (5 PRODUIT) · Références prix (Technique/2026 1028 References prix et benchmarks.md).

Sheet Tarifs
A1: Tarifs unitaires
A2: Prix publics relevés en octobre 2026 (fond vert) et hypothèses (texte bleu). Les formules des autres onglets pointent ici.
A4: Clé | B4: Poste | C4: Valeur | D4: Unité | E4: Nature | F4: Source | G4: Date | H4: Note
A5: fx | B5: Taux de change dollar → euro | C5: 0.877 | D5: € par $ | E5: Tarif public | F5: BCE, taux de référence 1 € = 1,1403 $ : https://www.ecb.europa.eu/stats/policy_and_exchange_rates/euro_reference_exchange_rates/html/eurofxref-graph-usd.en.html | G5: 25/09/2026 | H5: Dernier taux publié sur la page lue le 28/10/2026 ; à relire le jour du calcul.
A6: small_in | B6: Petit modèle, entrée (Mistral Small 4, point d'accès UE api.eu.mistral.ai, +10 %) | C6: 0.165 | D6: $ / M jetons | E6: Tarif public | F6: https://docs.mistral.ai/models/pricing (0,15 $) et https://docs.mistral.ai/inference/regional-inference (×1,1) | G6: 28/10/2026 | H6: Alternative : Claude Haiku 5.5 sur Bedrock UE 0,11 $ ; Scaleway mistral-small-3.2 0,15 € (Paris, sans surcoût).
A7: small_cached | B7: Petit modèle, entrée cachée (10 % du prix d'entrée) | C7: 0.0165 | D7: $ / M jetons | E7: Tarif public | F7: https://docs.mistral.ai/models/pricing | G7: 28/10/2026
A8: small_out | B8: Petit modèle, sortie | C8: 0.66 | D8: $ / M jetons | E8: Tarif public | F8: https://docs.mistral.ai/models/pricing (0,60 $ × 1,1) | G8: 28/10/2026
A9: mid_in | B9: Modèle moyen, entrée (Claude Sonnet 5.5, Amazon Bedrock profil UE, +10 %) | C9: 2.2 | D9: $ / M jetons | E9: Tarif public | F9: https://platform.claude.com/docs/en/about-claude/pricing (2 $) et https://platform.claude.com/docs/en/build-with-claude/claude-in-amazon-bedrock (+10 % régional) | G9: 28/10/2026 | H9: Alternatives : gpt-6.1-sol sur eu.api.openai.com 2,20 $ ; Mistral Medium 3.5 UE 1,65 $ ; Mistral Large 4 UE 1,50 $.
A10: mid_cached | B10: Modèle moyen, entrée cachée (lecture de cache, 5 % du prix d'entrée) | C10: 0.11 | D10: $ / M jetons | E10: Tarif public | F10: https://platform.claude.com/docs/en/build-with-claude/prompt-caching (0,10 $ × 1,1) | G10: 28/10/2026 | H10: Écriture de cache +25 % sur 5 min, non comptée ici (contexte stable réutilisé).
A11: mid_out | B11: Modèle moyen, sortie | C11: 11 | D11: $ / M jetons | E11: Tarif public | F11: https://platform.claude.com/docs/en/about-claude/pricing (10 $ × 1,1) | G11: 28/10/2026
A12: front_in | B12: Modèle frontière, entrée (Claude Opus 5.5, Bedrock profil UE, +10 %) | C12: 4.4 | D12: $ / M jetons | E12: Tarif public | F12: https://platform.claude.com/docs/en/about-claude/pricing (4 $ × 1,1) | G12: 28/10/2026 | H12: Escalade des cas difficiles seulement. Fable 5.1 (10 / 50 $) exclu : retention 30 jours imposée, pas de point d'accès UE.
A13: front_cached | B13: Modèle frontière, entrée cachée | C13: 0.22 | D13: $ / M jetons | E13: Tarif public | F13: https://platform.claude.com/docs/en/about-claude/pricing (0,20 $ × 1,1) | G13: 28/10/2026
A14: front_out | B14: Modèle frontière, sortie | C14: 22 | D14: $ / M jetons | E14: Tarif public | F14: https://platform.claude.com/docs/en/about-claude/pricing (20 $ × 1,1) | G14: 28/10/2026
A15: embed | B15: Embeddings (Mistral Embed, point d'accès UE) | C15: 0.11 | D15: $ / M jetons | E15: Tarif public | F15: https://docs.mistral.ai/models/pricing (0,10 $ × 1,1) ; Scaleway 0,10 € | G15: 28/10/2026
A16: search_call | B16: Recherche web (Brave Search API) | C16: 0.005 | D16: $ / requête | E16: Tarif public | F16: https://api-dashboard.search.brave.com/documentation/pricing (5 $ pour 1 000 requêtes) | G16: 28/10/2026 | H16: Alternatives : Exa 7 $, Tavily 8 $ pour 1 000. Rétention zéro sur offre Entreprise.
A17: places_call | B17: Google Places API (New) : moyenne d'une recherche textuelle Pro (32 $) et de deux fiches Pro (17 $) pour 1 000 | C17: 0.022 | D17: $ / requête | E17: Tarif public | F17: https://developers.google.com/maps/billing-and-pricing/pricing | G17: 28/10/2026 | H17: 5 000 événements gratuits par mois et par SKU : le pilote reste gratuit.
A18: page_read | B18: Lecture d'une page web (Firecrawl, offre Hobby : 19 $ pour 5 000 pages) | C18: 0.0038 | D18: $ / page | E18: Tarif public | F18: https://www.firecrawl.dev/pricing.md | G18: 28/10/2026 | H18: Jina Reader environ 0,0005 $ par page (source secondaire).
A19: browser_min | B19: Navigateur piloté dans le nuage, infrastructure et proxy résidentiel | C19: 0.012 | D19: $ / minute | E19: Tarif public | F19: Browserbase 0,12 $ par heure-navigateur (https://docs.browserbase.com/account/billing/plans.md) soit 0,002 $/min ; proxy résidentiel 10 $/Go, environ 1 Mo par minute soit 0,01 $/min | G19: 28/10/2026 | H19: Hors jetons du modèle qui pilote (comptés dans les appels moyens). Browser Use Cloud 0,02 $/h, Anchor 0,05 $/h : l'infrastructure est négligeable, le proxy et les jetons font le coût.
A20: support_min | B20: Support humain | C20: 0.5 | D20: € / minute | E20: Hypothèse | F20: 30 € HT de l'heure chargée (fondateur puis customer success) | G20: 28/10/2026 | H20: Cohérent avec l'embauche 1 du modèle 36 mois (4 500 € chargés).
A21: hosting_user | B21: Hébergement, stockage, connecteurs, par abonné et par mois | C21: 1.5 | D21: € / abonné | E21: Hypothèse | F21: Modèle 36 mois, central ; détail dans la réponse au cadrage § 3.5 | G21: 28/10/2026 | H21: Coût fixe de la plateforme réparti ; vaut à partir de ~300 abonnés.
A22: stripe_pct | B22: Frais de paiement, part variable : carte EEE 1,5 % + Stripe Billing 0,7 % + Stripe Tax 0,5 % | C22: 0.027 | D22: % | E22: Tarif public | F22: https://stripe.com/fr/pricing | G22: 28/10/2026 | H22: Par prélèvement SEPA : 0,35 € fixe + 1,2 %, soit 1,30 € sur 79 €.
A23: stripe_fixed | B23: Frais de paiement, part fixe (carte) | C23: 0.25 | D23: € / transaction | E23: Tarif public | F23: https://stripe.com/fr/pricing | G23: 28/10/2026
A25: Paliers de modèles retenus
A26: Palier | B26: Rôle | C26: Modèle recommandé | D26: Alternative UE | E26: Prix entrée ($/M) | F26: Prix sortie ($/M) | G26: Résidence des données | H26: Note
A27: Petit | B27: Tri des courriels, extraction d'échéances et d'entités, lecture de pages, lecture initiale en lot | C27: Mistral Small 4 sur api.eu.mistral.ai (Mistral AI, Paris ; traitement dans l'UE et l'AELE) | D27: Claude Haiku 5.5 via Amazon Bedrock profil UE ; Scaleway mistral-small-3.2 (Paris, rétention zéro par défaut) | E27: 0,165 (0,15 × 1,1) | F27: 0,66 | G27: UE / AELE ; rétention zéro sur demande (plan payant) | H27: Le socle lit les données les plus sensibles : un fournisseur européen y est préféré. Lot (−50 %) indisponible sur le point d'accès régional : l'activation M11 passe par le point d'accès global ou Scaleway.
A28: Moyen | B28: Planification des missions, appels d'outils, pilotage du navigateur, rédaction dans le ton de l'utilisateur | C28: Claude Sonnet 5.5 via Amazon Bedrock, profil d'inférence UE (données traitées dans les régions UE, dont Paris eu-west-3) | D28: gpt-6.1-sol sur eu.api.openai.com (+10 %, résidence UE sur approbation) ; Mistral Medium 3.5 ou Large 4 sur api.eu.mistral.ai | E28: 2,20 (2 × 1,1) | F28: 11,0 | G28: UE (profil Bedrock) ; AWS est sous-traitant ; rétention selon Bedrock | H28: Retenu pour les scores d'agents (tau2-bench, OSWorld) ; Mistral Large 4 testé en bascule au pilote, deux fois moins cher en sortie.
A29: Frontière | B29: Escalade après deux échecs du modèle moyen ; cas ambigus ; 5 % des appels moyens en base, plafond 10 % | C29: Claude Opus 5.5 via Amazon Bedrock profil UE | D29: gpt-6-astra (10 / 50 $) ; Gemini 4 Argon (2 / 10 $, 4 / 20 $ dès le 1er décembre 2026, sans option de région sur l'API Gemini) | E29: 4,40 (4 × 1,1) | F29: 22,0 | G29: UE (profil Bedrock) | H29: Fable 5.1 écarté : rétention 30 jours imposée et points d'accès régionaux limités aux États-Unis.

Sheet Missions
A1: Missions : paramètres et coût par exécution
A2: Une ligne par mission. Colonnes bleues = hypothèses à remplacer par les mesures du pilote. Fréquences pour un abonné Premium.
A4: # | B4: Mission | C4: Priorité | D4: Validation (A/C/X) | E4: Exécutions par mois (Premium) | F4: Appels petit modèle | G4: Entrée par appel (jetons) | H4: Part cachée | I4: Sortie par appel (jetons) | J4: Appels moyen | K4: Entrée par appel (jetons) | L4: Part cachée | M4: Sortie par appel (jetons) | N4: Part escaladée vers frontière | O4: Recherches web | P4: Appels Places | Q4: Lectures de page | R4: Navigateur piloté (min) | S4: Facteur de reprises | T4: Taux de réussite estimé (non mesuré) | U4: Durée (min) | V4: Part des échecs traités par un humain | W4: Minutes par traitement | X4: Jetons d'embedding | Y4: Coût modèles par exécution | Z4: Coût outils par exécution | AA4: Coût support par exécution | AB4: Coût total HT par exécution | AC4: Coût mensuel par abonné Premium | AD4: Part du coût mensuel | AE4: dont modèles / mois | AF4: dont outils / mois | AG4: dont support / mois
A5: M0 | B5: Socle : tri quotidien des courriels et de l'agenda (partagé par M1, M2, M8, M9) | C5: Socle | D5: A | E5: 30 | F5: 1 | G5: 20000 | H5: 0.2 | I5: 1500 | J5: 0 | K5: 0 | L5: 0 | M5: 0 | N5: 0 | O5: 0 | P5: 0 | Q5: 0 | R5: 0 | S5: 1.05 | T5: 0.97 | U5: 1 | V5: 0 | W5: 0 | X5: 2000 | Y5: =S5*(F5*((G5*(1-H5))*Tarifs!$C$6+G5*H5*Tarifs!$C$7+I5*Tarifs!$C$8)/1000000+(1-N5)*J5*((K5*(1-L5))*Tarifs!$C$9+K5*L5*Tarifs!$C$10+M5*Tarifs!$C$11)/1000000+N5*J5*((K5*(1-L5))*Tarifs!$C$12+K5*L5*Tarifs!$C$13+M5*Tarifs!$C$14)/1000000+X5*Tarifs!$C$15/1000000)*Tarifs!$C$5 | Z5: =S5*(O5*Tarifs!$C$16+P5*Tarifs!$C$17+Q5*Tarifs!$C$18+R5*Tarifs!$C$19)*Tarifs!$C$5 | AA5: =(1-T5)*V5*W5*Tarifs!$C$20 | AB5: =Y5+Z5+AA5 | AC5: =E5*AB5 | AD5: =IF($AC$17=0,0,AC5/$AC$17) | AE5: =E5*Y5 | AF5: =E5*Z5 | AG5: =E5*AA5
A6: M1 | B6: Briefing quotidien | C6: 1 | D6: A | E6: 30 | F6: 0 | G6: 0 | H6: 0 | I6: 0 | J6: 1 | K6: 8000 | L6: 0.5 | M6: 600 | N6: 0 | O6: 0 | P6: 0 | Q6: 0 | R6: 0 | S6: 1.05 | T6: 0.95 | U6: 1 | V6: 0.1 | W6: 3 | X6: 0 | Y6: =S6*(F6*((G6*(1-H6))*Tarifs!$C$6+G6*H6*Tarifs!$C$7+I6*Tarifs!$C$8)/1000000+(1-N6)*J6*((K6*(1-L6))*Tarifs!$C$9+K6*L6*Tarifs!$C$10+M6*Tarifs!$C$11)/1000000+N6*J6*((K6*(1-L6))*Tarifs!$C$12+K6*L6*Tarifs!$C$13+M6*Tarifs!$C$14)/1000000+X6*Tarifs!$C$15/1000000)*Tarifs!$C$5 | Z6: =S6*(O6*Tarifs!$C$16+P6*Tarifs!$C$17+Q6*Tarifs!$C$18+R6*Tarifs!$C$19)*Tarifs!$C$5 | AA6: =(1-T6)*V6*W6*Tarifs!$C$20 | AB6: =Y6+Z6+AA6 | AC6: =E6*AB6 | AD6: =IF($AC$17=0,0,AC6/$AC$17) | AE6: =E6*Y6 | AF6: =E6*Z6 | AG6: =E6*AA6
A7: M2 | B7: Suivi des échéances personnelles | C7: 1 | D7: A | E7: 8 | F7: 1 | G7: 6000 | H7: 0 | I7: 400 | J7: 1 | K7: 5000 | L7: 0.4 | M7: 300 | N7: 0 | O7: 0 | P7: 0 | Q7: 0 | R7: 0 | S7: 1.1 | T7: 0.9 | U7: 2 | V7: 0.1 | W7: 3 | X7: 0 | Y7: =S7*(F7*((G7*(1-H7))*Tarifs!$C$6+G7*H7*Tarifs!$C$7+I7*Tarifs!$C$8)/1000000+(1-N7)*J7*((K7*(1-L7))*Tarifs!$C$9+K7*L7*Tarifs!$C$10+M7*Tarifs!$C$11)/1000000+N7*J7*((K7*(1-L7))*Tarifs!$C$12+K7*L7*Tarifs!$C$13+M7*Tarifs!$C$14)/1000000+X7*Tarifs!$C$15/1000000)*Tarifs!$C$5 | Z7: =S7*(O7*Tarifs!$C$16+P7*Tarifs!$C$17+Q7*Tarifs!$C$18+R7*Tarifs!$C$19)*Tarifs!$C$5 | AA7: =(1-T7)*V7*W7*Tarifs!$C$20 | AB7: =Y7+Z7+AA7 | AC7: =E7*AB7 | AD7: =IF($AC$17=0,0,AC7/$AC$17) | AE7: =E7*Y7 | AF7: =E7*Z7 | AG7: =E7*AA7
A8: M3 | B8: Prise de rendez-vous de service (garage, coiffeur, artisan) | C8: 2 | D8: C | E8: 1 | F8: 2 | G8: 4000 | H8: 0 | I8: 300 | J8: 15 | K8: 12000 | L8: 0.4 | M8: 250 | N8: 0.05 | O8: 1 | P8: 3 | Q8: 0 | R8: 8 | S8: 1.4 | T8: 0.65 | U8: 12 | V8: 0.4 | W8: 6 | X8: 0 | Y8: =S8*(F8*((G8*(1-H8))*Tarifs!$C$6+G8*H8*Tarifs!$C$7+I8*Tarifs!$C$8)/1000000+(1-N8)*J8*((K8*(1-L8))*Tarifs!$C$9+K8*L8*Tarifs!$C$10+M8*Tarifs!$C$11)/1000000+N8*J8*((K8*(1-L8))*Tarifs!$C$12+K8*L8*Tarifs!$C$13+M8*Tarifs!$C$14)/1000000+X8*Tarifs!$C$15/1000000)*Tarifs!$C$5 | Z8: =S8*(O8*Tarifs!$C$16+P8*Tarifs!$C$17+Q8*Tarifs!$C$18+R8*Tarifs!$C$19)*Tarifs!$C$5 | AA8: =(1-T8)*V8*W8*Tarifs!$C$20 | AB8: =Y8+Z8+AA8 | AC8: =E8*AB8 | AD8: =IF($AC$17=0,0,AC8/$AC$17) | AE8: =E8*Y8 | AF8: =E8*Z8 | AG8: =E8*AA8
A9: M4 | B9: Réservation de restaurant | C9: 2 | D9: C | E9: 2 | F9: 2 | G9: 4000 | H9: 0 | I9: 300 | J9: 12 | K9: 12000 | L9: 0.4 | M9: 250 | N9: 0.05 | O9: 0 | P9: 4 | Q9: 0 | R9: 6 | S9: 1.3 | T9: 0.7 | U9: 10 | V9: 0.3 | W9: 5 | X9: 0 | Y9: =S9*(F9*((G9*(1-H9))*Tarifs!$C$6+G9*H9*Tarifs!$C$7+I9*Tarifs!$C$8)/1000000+(1-N9)*J9*((K9*(1-L9))*Tarifs!$C$9+K9*L9*Tarifs!$C$10+M9*Tarifs!$C$11)/1000000+N9*J9*((K9*(1-L9))*Tarifs!$C$12+K9*L9*Tarifs!$C$13+M9*Tarifs!$C$14)/1000000+X9*Tarifs!$C$15/1000000)*Tarifs!$C$5 | Z9: =S9*(O9*Tarifs!$C$16+P9*Tarifs!$C$17+Q9*Tarifs!$C$18+R9*Tarifs!$C$19)*Tarifs!$C$5 | AA9: =(1-T9)*V9*W9*Tarifs!$C$20 | AB9: =Y9+Z9+AA9 | AC9: =E9*AB9 | AD9: =IF($AC$17=0,0,AC9/$AC$17) | AE9: =E9*Y9 | AF9: =E9*Z9 | AG9: =E9*AA9
A10: M5 | B10: Organisation d'un déplacement privé | C10: 2 | D10: C | E10: 0.5 | F10: 4 | G10: 8000 | H10: 0 | I10: 500 | J10: 6 | K10: 15000 | L10: 0.3 | M10: 800 | N10: 0.1 | O10: 8 | P10: 0 | Q10: 10 | R10: 0 | S10: 1.2 | T10: 0.75 | U10: 20 | V10: 0.2 | W10: 8 | X10: 0 | Y10: =S10*(F10*((G10*(1-H10))*Tarifs!$C$6+G10*H10*Tarifs!$C$7+I10*Tarifs!$C$8)/1000000+(1-N10)*J10*((K10*(1-L10))*Tarifs!$C$9+K10*L10*Tarifs!$C$10+M10*Tarifs!$C$11)/1000000+N10*J10*((K10*(1-L10))*Tarifs!$C$12+K10*L10*Tarifs!$C$13+M10*Tarifs!$C$14)/1000000+X10*Tarifs!$C$15/1000000)*Tarifs!$C$5 | Z10: =S10*(O10*Tarifs!$C$16+P10*Tarifs!$C$17+Q10*Tarifs!$C$18+R10*Tarifs!$C$19)*Tarifs!$C$5 | AA10: =(1-T10)*V10*W10*Tarifs!$C$20 | AB10: =Y10+Z10+AA10 | AC10: =E10*AB10 | AD10: =IF($AC$17=0,0,AC10/$AC$17) | AE10: =E10*Y10 | AF10: =E10*Z10 | AG10: =E10*AA10
A11: M6 | B11: Brouillons de courriels personnels | C11: 1 | D11: C | E11: 6 | F11: 0 | G11: 0 | H11: 0 | I11: 0 | J11: 1 | K11: 6000 | L11: 0.5 | M11: 500 | N11: 0 | O11: 0 | P11: 0 | Q11: 0 | R11: 0 | S11: 1.15 | T11: 0.85 | U11: 1 | V11: 0.05 | W11: 2 | X11: 0 | Y11: =S11*(F11*((G11*(1-H11))*Tarifs!$C$6+G11*H11*Tarifs!$C$7+I11*Tarifs!$C$8)/1000000+(1-N11)*J11*((K11*(1-L11))*Tarifs!$C$9+K11*L11*Tarifs!$C$10+M11*Tarifs!$C$11)/1000000+N11*J11*((K11*(1-L11))*Tarifs!$C$12+K11*L11*Tarifs!$C$13+M11*Tarifs!$C$14)/1000000+X11*Tarifs!$C$15/1000000)*Tarifs!$C$5 | Z11: =S11*(O11*Tarifs!$C$16+P11*Tarifs!$C$17+Q11*Tarifs!$C$18+R11*Tarifs!$C$19)*Tarifs!$C$5 | AA11: =(1-T11)*V11*W11*Tarifs!$C$20 | AB11: =Y11+Z11+AA11 | AC11: =E11*AB11 | AD11: =IF($AC$17=0,0,AC11/$AC$17) | AE11: =E11*Y11 | AF11: =E11*Z11 | AG11: =E11*AA11
A12: M7 | B12: Coordination de l'agenda familial | C12: 2 | D12: C | E12: 4 | F12: 1 | G12: 5000 | H12: 0 | I12: 300 | J12: 1 | K12: 8000 | L12: 0.5 | M12: 400 | N12: 0 | O12: 0 | P12: 0 | Q12: 0 | R12: 0 | S12: 1.1 | T12: 0.8 | U12: 2 | V12: 0.1 | W12: 3 | X12: 0 | Y12: =S12*(F12*((G12*(1-H12))*Tarifs!$C$6+G12*H12*Tarifs!$C$7+I12*Tarifs!$C$8)/1000000+(1-N12)*J12*((K12*(1-L12))*Tarifs!$C$9+K12*L12*Tarifs!$C$10+M12*Tarifs!$C$11)/1000000+N12*J12*((K12*(1-L12))*Tarifs!$C$12+K12*L12*Tarifs!$C$13+M12*Tarifs!$C$14)/1000000+X12*Tarifs!$C$15/1000000)*Tarifs!$C$5 | Z12: =S12*(O12*Tarifs!$C$16+P12*Tarifs!$C$17+Q12*Tarifs!$C$18+R12*Tarifs!$C$19)*Tarifs!$C$5 | AA12: =(1-T12)*V12*W12*Tarifs!$C$20 | AB12: =Y12+Z12+AA12 | AC12: =E12*AB12 | AD12: =IF($AC$17=0,0,AC12/$AC$17) | AE12: =E12*Y12 | AF12: =E12*Z12 | AG12: =E12*AA12
A13: M8 | B13: Suivi des abonnements | C13: 3 | D13: C | E13: 1 | F13: 1 | G13: 10000 | H13: 0 | I13: 500 | J13: 1.5 | K13: 6000 | L13: 0.4 | M13: 400 | N13: 0 | O13: 0 | P13: 0 | Q13: 0 | R13: 0 | S13: 1.1 | T13: 0.85 | U13: 3 | V13: 0.1 | W13: 4 | X13: 0 | Y13: =S13*(F13*((G13*(1-H13))*Tarifs!$C$6+G13*H13*Tarifs!$C$7+I13*Tarifs!$C$8)/1000000+(1-N13)*J13*((K13*(1-L13))*Tarifs!$C$9+K13*L13*Tarifs!$C$10+M13*Tarifs!$C$11)/1000000+N13*J13*((K13*(1-L13))*Tarifs!$C$12+K13*L13*Tarifs!$C$13+M13*Tarifs!$C$14)/1000000+X13*Tarifs!$C$15/1000000)*Tarifs!$C$5 | Z13: =S13*(O13*Tarifs!$C$16+P13*Tarifs!$C$17+Q13*Tarifs!$C$18+R13*Tarifs!$C$19)*Tarifs!$C$5 | AA13: =(1-T13)*V13*W13*Tarifs!$C$20 | AB13: =Y13+Z13+AA13 | AC13: =E13*AB13 | AD13: =IF($AC$17=0,0,AC13/$AC$17) | AE13: =E13*Y13 | AF13: =E13*Z13 | AG13: =E13*AA13
A14: M9 | B14: Relances et engagements en attente | C14: 1 | D14: C | E14: 4 | F14: 0.5 | G14: 4000 | H14: 0 | I14: 200 | J14: 1 | K14: 4000 | L14: 0.5 | M14: 300 | N14: 0 | O14: 0 | P14: 0 | Q14: 0 | R14: 0 | S14: 1.1 | T14: 0.85 | U14: 1 | V14: 0.05 | W14: 2 | X14: 0 | Y14: =S14*(F14*((G14*(1-H14))*Tarifs!$C$6+G14*H14*Tarifs!$C$7+I14*Tarifs!$C$8)/1000000+(1-N14)*J14*((K14*(1-L14))*Tarifs!$C$9+K14*L14*Tarifs!$C$10+M14*Tarifs!$C$11)/1000000+N14*J14*((K14*(1-L14))*Tarifs!$C$12+K14*L14*Tarifs!$C$13+M14*Tarifs!$C$14)/1000000+X14*Tarifs!$C$15/1000000)*Tarifs!$C$5 | Z14: =S14*(O14*Tarifs!$C$16+P14*Tarifs!$C$17+Q14*Tarifs!$C$18+R14*Tarifs!$C$19)*Tarifs!$C$5 | AA14: =(1-T14)*V14*W14*Tarifs!$C$20 | AB14: =Y14+Z14+AA14 | AC14: =E14*AB14 | AD14: =IF($AC$17=0,0,AC14/$AC$17) | AE14: =E14*Y14 | AF14: =E14*Z14 | AG14: =E14*AA14
A15: M10 | B15: Préparation d'un événement personnel | C15: 3 | D15: C | E15: 0.5 | F15: 1 | G15: 6000 | H15: 0 | I15: 400 | J15: 3 | K15: 10000 | L15: 0.3 | M15: 800 | N15: 0.05 | O15: 3 | P15: 1 | Q15: 0 | R15: 3 | S15: 1.2 | T15: 0.7 | U15: 15 | V15: 0.2 | W15: 5 | X15: 0 | Y15: =S15*(F15*((G15*(1-H15))*Tarifs!$C$6+G15*H15*Tarifs!$C$7+I15*Tarifs!$C$8)/1000000+(1-N15)*J15*((K15*(1-L15))*Tarifs!$C$9+K15*L15*Tarifs!$C$10+M15*Tarifs!$C$11)/1000000+N15*J15*((K15*(1-L15))*Tarifs!$C$12+K15*L15*Tarifs!$C$13+M15*Tarifs!$C$14)/1000000+X15*Tarifs!$C$15/1000000)*Tarifs!$C$5 | Z15: =S15*(O15*Tarifs!$C$16+P15*Tarifs!$C$17+Q15*Tarifs!$C$18+R15*Tarifs!$C$19)*Tarifs!$C$5 | AA15: =(1-T15)*V15*W15*Tarifs!$C$20 | AB15: =Y15+Z15+AA15 | AC15: =E15*AB15 | AD15: =IF($AC$17=0,0,AC15/$AC$17) | AE15: =E15*Y15 | AF15: =E15*Z15 | AG15: =E15*AA15
A16: M11 | B16: Activation : lecture initiale de la boîte et profil (une fois par nouvel abonné) | C16: Socle | D16: A | E16: 0 | F16: 1 | G16: 400000 | H16: 0 | I16: 20000 | J16: 1 | K16: 15000 | L16: 0 | M16: 800 | N16: 0 | O16: 0 | P16: 0 | Q16: 0 | R16: 0 | S16: 1 | T16: 0.95 | U16: 30 | V16: 0.1 | W16: 5 | X16: 400000 | Y16: =S16*(F16*((G16*(1-H16))*Tarifs!$C$6+G16*H16*Tarifs!$C$7+I16*Tarifs!$C$8)/1000000+(1-N16)*J16*((K16*(1-L16))*Tarifs!$C$9+K16*L16*Tarifs!$C$10+M16*Tarifs!$C$11)/1000000+N16*J16*((K16*(1-L16))*Tarifs!$C$12+K16*L16*Tarifs!$C$13+M16*Tarifs!$C$14)/1000000+X16*Tarifs!$C$15/1000000)*Tarifs!$C$5 | Z16: =S16*(O16*Tarifs!$C$16+P16*Tarifs!$C$17+Q16*Tarifs!$C$18+R16*Tarifs!$C$19)*Tarifs!$C$5 | AA16: =(1-T16)*V16*W16*Tarifs!$C$20 | AB16: =Y16+Z16+AA16 | AC16: =E16*AB16 | AD16: =IF($AC$17=0,0,AC16/$AC$17) | AE16: =E16*Y16 | AF16: =E16*Z16 | AG16: =E16*AA16
B17: Total mensuel, abonné Premium (M0 à M10) | E17: =SUM(E5:E16) | AC17: =SUM(AC5:AC16) | AE17: =SUM(AE5:AE16) | AF17: =SUM(AF5:AF16) | AG17: =SUM(AG5:AG16)
B18: Coût moyen par exécution (toutes missions, hors M11) | AB18: =AC17/E17
B19: Coût moyen par exécution, hors socle M0 (missions visibles 1 à 10) | AB19: =(AC17-AC5)/(E17-E5)

Sheet Synthèse
A1: Synthèse : coût variable par abonné et par offre
A2: Multiplicateurs de fréquence par offre (bleu) appliqués aux missions. Comparaison avec l'hypothèse Finance H03 (18 € HT) et avec le modèle 36 mois.
A4: # | B4: Mission | C4: Coût par exécution | D4: Personal : multiplicateur | E4: Premium : multiplicateur | F4: Family : multiplicateur | G4: Personal : exécutions / mois | H4: Premium : exécutions / mois | I4: Family : exécutions / mois | J4: Personal : coût / mois | K4: Premium : coût / mois | L4: Family : coût / mois
A5: M0 | B5: Socle : tri quotidien des courriels et de l'agenda (partagé par M1, M2, M8, M9) | C5: =Missions!AB5 | D5: 1 | E5: 1 | F5: 1 | G5: =D5*Missions!E5 | H5: =E5*Missions!E5 | I5: =F5*Missions!E5 | J5: =G5*$C5 | K5: =H5*$C5 | L5: =I5*$C5
A6: M1 | B6: Briefing quotidien | C6: =Missions!AB6 | D6: 0.25 | E6: 1 | F6: 1 | G6: =D6*Missions!E6 | H6: =E6*Missions!E6 | I6: =F6*Missions!E6 | J6: =G6*$C6 | K6: =H6*$C6 | L6: =I6*$C6
A7: M2 | B7: Suivi des échéances personnelles | C7: =Missions!AB7 | D7: 1 | E7: 1 | F7: 1.5 | G7: =D7*Missions!E7 | H7: =E7*Missions!E7 | I7: =F7*Missions!E7 | J7: =G7*$C7 | K7: =H7*$C7 | L7: =I7*$C7
A8: M3 | B8: Prise de rendez-vous de service (garage, coiffeur, artisan) | C8: =Missions!AB8 | D8: 0 | E8: 1 | F8: 2 | G8: =D8*Missions!E8 | H8: =E8*Missions!E8 | I8: =F8*Missions!E8 | J8: =G8*$C8 | K8: =H8*$C8 | L8: =I8*$C8
A9: M4 | B9: Réservation de restaurant | C9: =Missions!AB9 | D9: 0 | E9: 1 | F9: 2 | G9: =D9*Missions!E9 | H9: =E9*Missions!E9 | I9: =F9*Missions!E9 | J9: =G9*$C9 | K9: =H9*$C9 | L9: =I9*$C9
A10: M5 | B10: Organisation d'un déplacement privé | C10: =Missions!AB10 | D10: 0 | E10: 1 | F10: 1.5 | G10: =D10*Missions!E10 | H10: =E10*Missions!E10 | I10: =F10*Missions!E10 | J10: =G10*$C10 | K10: =H10*$C10 | L10: =I10*$C10
A11: M6 | B11: Brouillons de courriels personnels | C11: =Missions!AB11 | D11: 0.5 | E11: 1 | F11: 1.5 | G11: =D11*Missions!E11 | H11: =E11*Missions!E11 | I11: =F11*Missions!E11 | J11: =G11*$C11 | K11: =H11*$C11 | L11: =I11*$C11
A12: M7 | B12: Coordination de l'agenda familial | C12: =Missions!AB12 | D12: 0 | E12: 1 | F12: 3 | G12: =D12*Missions!E12 | H12: =E12*Missions!E12 | I12: =F12*Missions!E12 | J12: =G12*$C12 | K12: =H12*$C12 | L12: =I12*$C12
A13: M8 | B13: Suivi des abonnements | C13: =Missions!AB13 | D13: 1 | E13: 1 | F13: 1.5 | G13: =D13*Missions!E13 | H13: =E13*Missions!E13 | I13: =F13*Missions!E13 | J13: =G13*$C13 | K13: =H13*$C13 | L13: =I13*$C13
A14: M9 | B14: Relances et engagements en attente | C14: =Missions!AB14 | D14: 0.5 | E14: 1 | F14: 1.5 | G14: =D14*Missions!E14 | H14: =E14*Missions!E14 | I14: =F14*Missions!E14 | J14: =G14*$C14 | K14: =H14*$C14 | L14: =I14*$C14
A15: M10 | B15: Préparation d'un événement personnel | C15: =Missions!AB15 | D15: 0 | E15: 1 | F15: 2 | G15: =D15*Missions!E15 | H15: =E15*Missions!E15 | I15: =F15*Missions!E15 | J15: =G15*$C15 | K15: =H15*$C15 | L15: =I15*$C15
A16: M11 | B16: Activation : lecture initiale de la boîte et profil (une fois par nouvel abonné) | C16: =Missions!AB16 | D16: 0 | E16: 0 | F16: 0 | G16: =D16*Missions!E16 | H16: =E16*Missions!E16 | I16: =F16*Missions!E16 | J16: =G16*$C16 | K16: =H16*$C16 | L16: =I16*$C16
B17: Exécutions et coût IA, outils et support par mois | G17: =SUM(G5:G16) | H17: =SUM(H5:H16) | I17: =SUM(I5:I16) | J17: =SUM(J5:J16) | K17: =SUM(K5:K16) | L17: =SUM(L5:L16)
B19: Par abonné et par mois | C19: Personal | D19: Premium | E19: Family
B20: Prix TTC | C20: 29 | D20: 79 | E20: 129
B21: Prix HT (TVA 20 %) | C21: =C20/1.2 | D21: =D20/1.2 | E21: =E20/1.2
B22: Exécutions par mois (socle compris) | C22: =G17 | D22: =H17 | E22: =I17
B23: Missions visibles par mois (hors socle M0) | C23: =G17-G5 | D23: =H17-H5 | E23: =I17-I5
B24: Missions par mois dans le modèle 36 mois | C24: 20 | D24: 60 | E24: 90
B25: Coût IA, outils et support (ce classeur) | C25: =J17 | D25: =K17 | E25: =L17
B26: Hébergement, stockage, connecteurs (par abonné) | C26: =Tarifs!$C$21 | D26: =Tarifs!$C$21 | E26: =Tarifs!$C$21
B27: Frais de paiement | C27: =C20*Tarifs!$C$22+Tarifs!$C$23 | D27: =D20*Tarifs!$C$22+Tarifs!$C$23 | E27: =E20*Tarifs!$C$22+Tarifs!$C$23
B28: Coût variable total HT | C28: =C25+C26+C27 | D28: =D25+D26+D27 | E28: =E25+E26+E27
B29: Hypothèse Finance H03 (coût variable) | D29: 18
B30: Modèle 36 mois, central : missions × 0,18 € + 1,50 € + 3,00 € | C30: =C24*0.18+1.5+3 | D30: =D24*0.18+1.5+3 | E30: =E24*0.18+1.5+3
B31: Modèle 36 mois, prudent : missions × 0,30 € + 2,00 € + 5,00 € | C31: =C24*0.30+2+5 | D31: =D24*0.30+2+5 | E31: =E24*0.30+2+5
B32: Coût moyen par mission visible (ce classeur, socle réparti) | C32: =IF(C23=0,0,C25/C23) | D32: =IF(D23=0,0,D25/D23) | E32: =IF(E23=0,0,E25/E23)
B33: Contribution par abonné (prix HT − coût variable) | C33: =C21-C28 | D33: =D21-D28 | E33: =E21-E28
B34: Marge variable | C34: =IF(C21=0,0,C33/C21) | D34: =IF(D21=0,0,D33/D21) | E34: =IF(E21=0,0,E33/E21)
B36: Coût d'activation (M11, une fois par nouvel abonné) | C36: =Missions!AB16
B37: Part des missions à navigateur piloté (M3, M4, M10) dans le coût Premium | C37: =(K8+K9+K15)/K17
B39: Lecture
B40: Le coût variable de ce classeur est inférieur à l'hypothèse H03 de 18 € : la différence est une marge de prudence, pas une économie acquise. Le modèle 36 mois conserve 0,18 € par mission en central et 0,30 € en prudent tant que le pilote n'a pas mesuré.
B41: Les trois missions à navigateur piloté (prise de rendez-vous, restaurant, événement) concentrent l'essentiel du coût : ce sont elles qu'il faut mesurer en premier et plafonner (onglet Protections).
B42: Le coût d'activation (lecture initiale de la boîte, M11) se traite comme un coût d'acquisition : il s'ajoute au CAC, pas au coût mensuel.
B43: Les multiplicateurs par offre sont des hypothèses de conception : Personal reçoit un briefing hebdomadaire et les missions de lecture ; Family double les missions de coordination et de réservation.

Sheet Sensibilité
A1: Sensibilité : coût variable Premium par mois
A2: Variations linéaires des composantes (modèles, outils, reprises, support, change). Chaque ligne recalcule le coût IA, outils et support de l'abonné Premium.
A4: Cas | B4: Hypothèse | C4: Coût IA, outils, support (€ / mois) | D4: Écart vs base | E4: Coût variable total (€ / mois) | F4: Marge variable Premium
A5: Base | B5: Paramètres des onglets Tarifs et Missions | C5: =Missions!AE17+Missions!AF17+Missions!AG17 | D5: =C5-C$5 | E5: =C5+Synthèse!D26+Synthèse!D27 | F5: =(Synthèse!D21-E5)/Synthèse!D21
A6: Prix des modèles × 2 | B6: Hausse de prix ou routage dégradé (tout en moyen) | C6: =Missions!AE17*2+Missions!AF17+Missions!AG17 | D6: =C6-C$5 | E6: =C6+Synthèse!D26+Synthèse!D27 | F6: =(Synthèse!D21-E6)/Synthèse!D21
A7: Prix des modèles × 0,5 | B7: Baisse de prix annuelle observée, ou routage plus agressif vers le petit modèle | C7: =Missions!AE17*0.5+Missions!AF17+Missions!AG17 | D7: =C7-C$5 | E7: =C7+Synthèse!D26+Synthèse!D27 | F7: =(Synthèse!D21-E7)/Synthèse!D21
A8: Sans cache de contexte | B8: Le cache ne fonctionne pas (facteur moyen 1,35 sur les modèles) | C8: =Missions!AE17*1.35+Missions!AF17+Missions!AG17 | D8: =C8-C$5 | E8: =C8+Synthèse!D26+Synthèse!D27 | F8: =(Synthèse!D21-E8)/Synthèse!D21
A9: Outils × 2 | B9: Navigateur piloté et recherches deux fois plus chers ou deux fois plus longs | C9: =Missions!AE17+Missions!AF17*2+Missions!AG17 | D9: =C9-C$5 | E9: =C9+Synthèse!D26+Synthèse!D27 | F9: =(Synthèse!D21-E9)/Synthèse!D21
A10: Reprises +50 % | B10: Facteur de reprises 1,5 fois plus élevé sur modèles et outils | C10: =(Missions!AE17+Missions!AF17)*1.5+Missions!AG17 | D10: =C10-C$5 | E10: =C10+Synthèse!D26+Synthèse!D27 | F10: =(Synthèse!D21-E10)/Synthèse!D21
A11: Support × 3 | B11: Taux d'échec ou minutes de support trois fois plus élevés | C11: =Missions!AE17+Missions!AF17+Missions!AG17*3 | D11: =C11-C$5 | E11: =C11+Synthèse!D26+Synthèse!D27 | F11: =(Synthèse!D21-E11)/Synthèse!D21
A12: Dollar +10 % | B12: Change défavorable | C12: =(Missions!AE17+Missions!AF17)*1.1+Missions!AG17 | D12: =C12-C$5 | E12: =C12+Synthèse!D26+Synthèse!D27 | F12: =(Synthèse!D21-E12)/Synthèse!D21
A13: Tout en frontière | B13: Aucun routage : tous les appels moyens au prix frontière (approximation : modèles × ratio frontière/moyen) | C13: =Missions!AE17*(Tarifs!$C$12/Tarifs!$C$9)+Missions!AF17+Missions!AG17 | D13: =C13-C$5 | E13: =C13+Synthèse!D26+Synthèse!D27 | F13: =(Synthèse!D21-E13)/Synthèse!D21
A14: Réservations : volume × 3 et coût × 2 | B14: Les missions à navigateur piloté (M3, M4, M10) trois fois plus fréquentes et deux fois plus chères | C14: =Missions!AE17+Missions!AF17+Missions!AG17+5*(Synthèse!K8+Synthèse!K9+Synthèse!K15) | D14: =C14-C$5 | E14: =C14+Synthèse!D26+Synthèse!D27 | F14: =(Synthèse!D21-E14)/Synthèse!D21
A15: Cumul défavorable | B15: Modèles × 2, outils × 2, reprises +50 %, support × 3 | C15: =(Missions!AE17*2+Missions!AF17*2)*1.5+Missions!AG17*3 | D15: =C15-C$5 | E15: =C15+Synthèse!D26+Synthèse!D27 | F15: =(Synthèse!D21-E15)/Synthèse!D21
A17: Seuils
A18: Hypothèse Finance H03 | C18: 18
A19: Seuil de la porte d'évidence (coût variable mesuré ≤ 18 € HT) | C19: =IF(E5<=18,"Tenu en base","Dépassé en base")
A20: Coût par mission au-delà duquel le plan prévoit limites d'usage et test de prix (0,30 €) | C20: =Missions!AB18

Sheet Protections
A1: Protections contre les coûts excessifs
A2: Plafonds par offre (bleu) et coût au plafond. Un abonné qui atteint un plafond est informé ; le dépassement est une décision de Produit, pas un automatisme.
A4: Protection | B4: Règle | C4: Personal | D4: Premium | E4: Family | F4: Note
A5: Plafond de missions par mois | B5: Au-delà, le majordome propose mais n'exécute plus les missions C jusqu'au mois suivant ; l'utilisateur est prévenu à 80 %. | C5: 30 | D5: 90 | E5: 150 | F5: Le modèle 36 mois suppose 20 / 60 / 90 missions : le plafond laisse 50 % de marge d'usage.
A6: Plafond de navigateur piloté (minutes par mois) | B6: Les missions 3, 4 et 10 consomment le quota ; au plafond, le majordome prépare la réservation et laisse l'utilisateur cliquer. | C6: 0 | D6: 60 | E6: 120 | F6: Le navigateur piloté est le poste le plus cher et le moins fiable.
A7: Budget de jetons par mission | B7: Chaque mission a un budget de jetons et d'étapes ; dépassement = arrêt propre, message à l'utilisateur, ligne au journal. | C7: 200 k | D7: 400 k | E7: 400 k | F7: Empêche les boucles. Valeurs à caler sur les mesures des missions 3 et 4.
A8: Escalade vers le modèle frontière | B8: Seulement après deux échecs du modèle moyen, et jamais pour le socle. | C8: non | D8: ≤ 10 % | E8: ≤ 10 % | F8: Part des appels moyens escaladés ; 5 % en base dans l'onglet Missions.
A9: Alerte de coût par abonné | B9: Si le coût IA et outils du mois dépasse 25 % du prix HT, alerte interne ; à 40 %, revue manuelle et proposition de changement d'offre. | C9: 25 % / 40 % | D9: 25 % / 40 % | E9: 25 % / 40 % | F9: Le classeur donne le coût au plafond ci-dessous.
A10: Coupe-circuit global | B10: Si la dépense API journalière dépasse 3 fois la moyenne glissante sur 7 jours, les missions C sont suspendues et l'astreinte est prévenue. | C10: oui | D10: oui | E10: oui | F10: Protège contre un bug ou une injection qui ferait boucler des missions.
A11: Clés et quotas fournisseurs | B11: Clés par environnement, quotas durs chez chaque fournisseur (plafond mensuel en dollars), rotation trimestrielle. | C11: oui | D11: oui | E11: oui | F11: Les fournisseurs permettent un plafond de dépense mensuel au niveau du compte.
A13: Coût au plafond (ordre de grandeur)
A14: Poste | B14: Formule | C14: Personal | D14: Premium | E14: Family | F14: Note
A15: Réservations possibles au plafond de navigateur (minutes ÷ 7 par réservation) | B15: plafond de minutes ÷ 7 | C15: =C6/7 | D15: =D6/7 | E15: =E6/7
A16: Coût des réservations au plafond (× coût moyen d'une réservation M3, M4) | B16: réservations × moyenne(M3, M4) | C16: =C15*AVERAGE(Missions!AB8,Missions!AB9) | D16: =D15*AVERAGE(Missions!AB8,Missions!AB9) | E16: =E15*AVERAGE(Missions!AB8,Missions!AB9)
A17: Autres missions au plafond (× coût moyen des missions sans navigateur, socle compris) | B17: (plafond missions − réservations) × moyenne hors M3, M4, M10 | C17: =MAX(0,C5-C15)*((Missions!AC17-Missions!AC8-Missions!AC9-Missions!AC15)/(Missions!E17-Missions!E8-Missions!E9-Missions!E15)) | D17: =MAX(0,D5-D15)*((Missions!AC17-Missions!AC8-Missions!AC9-Missions!AC15)/(Missions!E17-Missions!E8-Missions!E9-Missions!E15)) | E17: =MAX(0,E5-E15)*((Missions!AC17-Missions!AC8-Missions!AC9-Missions!AC15)/(Missions!E17-Missions!E8-Missions!E9-Missions!E15))
A18: Coût maximal IA, outils et support par abonné et par mois | C18: =C16+C17 | D18: =D16+D17 | E18: =E16+E17
A19: En part du prix HT | C19: =C18/(29/1.2) | D19: =D18/(79/1.2) | E19: =E18/(129/1.2)

Sheet Plan de charge
A1: Plan de charge et budget MVP
A2: Jours par profil et par chantier, deux variantes : Lean (un développeur senior externe, fondateurs à la manœuvre) et Confort (deux développeurs). Taux journaliers sourcés (vert) ou hypothèses (bleu).
A4: Taux journaliers HT
A5: Profil | B5: TJM retenu (€ HT) | C5: Fourchette source | D5: Nature | E5: Source | F5: Date
A6: Développeur full-stack senior (externe) | B6: 650 | C6: Hays 2026 Paris, 8 ans et plus : 650 ; Paris confirmé 550 à 680, senior 670 et plus (La Fabrique du Net, juil. 2026) | D6: Tarif public | E6: https://www.blogdumoderateur.com/freelance-tech-taux-journaliers-moyens-metier-2026/ (étude Hays 2026) ; https://www.lafabriquedunet.fr/agences/tendances/tarifs-des-developpeurs-freelances-dans-les-grandes-villes-de-france | F6: 28/10/2026
A7: Ingénieur IA / LLM (externe) | B7: 800 | C7: Malt Tech Trends 2025 : expert 670 à 750 (moyennes européennes 2024) ; Michael Page Île-de-France : 600 à 1 000 | D7: Tarif public | E7: https://pages.malt.fr/hubfs/NEW%20-%20E-books%20visuals/Malt%20Tech%20Trends%202025/Malt%20Tech%20Trends%202025%20-%20FR.pdf ; https://www.michaelpage.fr/grilles-de-salaires/technology/ | F7: 28/10/2026
A8: Product designer UX/UI (externe) | B8: 550 | C8: 450 à 700, médiane environ 510 (baromètre compilé 2026) ; moyenne 423 (Kicklox / RH Solutions 2025) | D8: Tarif public | E8: https://www.freelance-solution.fr/barometre-tjm-freelance-2026/ ; https://www.rh-solutions.com/app/uploads/2025/12/RHS-Etude-2025-les-TJM-freelances_compressed.pdf | F8: 28/10/2026
A9: Pentest application et API, jour d'auditeur (prestataire) | B9: 1150 | C9: 900 à 1 500 (PASSI 1 200 à 1 500, non PASSI 900 à 1 200) ; pentest boîte grise app + API 8 000 à 12 000 € plus contre-test 1 000 à 2 500 € | D9: Tarif public | E9: https://kolonell.com/fr/blog/prix-pentest-application-web-pme-france-2026 (1er oct. 2026, source fournisseur) | F9: 28/10/2026
A10: Consultant RGPD / AIPD (externe) | B10: 850 | C10: 800 à 900 (tarifs illustratifs ; aucun barème publié) ; AIPD estimée 4 à 8 jours | D10: Hypothèse | E10: https://www.legiscope.com/blog/dpo-externalise-cout.html ; https://donneespersonnelles.fr/dpo-externalise-tarifs | F10: 28/10/2026
A11: Fondateur, architecture et sécurité (Malik) | B11: 0 | C11: non facturé | D11: Hypothèse | E11: Fondateurs non rémunérés M1 à M12 (hypothèse Finance) | F11: 28/10/2026
A12: Fondateur, produit et recette (Steve) | B12: 0 | C12: non facturé | D12: Hypothèse | E12: Idem | F12: 28/10/2026
A13: Fondateur, exploitation et support (Isaac) | B13: 0 | C13: non facturé | D13: Hypothèse | E13: Idem | F13: 28/10/2026
A15: Chantiers
A16: Chantier | B16: Profil | C16: Jours Lean | D16: Jours Confort | E16: Coût Lean (€ HT) | F16: Coût Confort (€ HT) | G16: Dépendances et notes
A17: W0 Architecture, choix techniques, revue de sécurité | B17: Fondateur, architecture et sécurité (Malik) | C17: 15 | D17: 15 | E17: =C17*$B$11 | F17: =D17*$B$11 | G17: Avant tout code : schéma de données, politique A/C/X, mandats, journal. Dépendance : D-01 (qui continue) et D-02 (nom, domaine).
A18: W1 Socle : comptes, OAuth Google, ingestion, mémoire, journal | B18: Développeur full-stack senior (externe) | C18: 18 | D18: 15 | E18: =C18*$B$6 | F18: =D18*$B$6 | G18: Connecteur Gmail/Agenda/Drive en périmètres restreints ; chiffrement des jetons OAuth ; file de missions durable (PostgreSQL).
A19: W2 Passerelle modèles, orchestrateur, moteur de politique | B19: Ingénieur IA / LLM (externe) | C19: 16 | D19: 14 | E19: =C19*$B$7 | F19: =D19*$B$7 | G19: Routage petit/moyen/frontière, cache de contexte, budgets par mission, traces de coût. Dépendance : W1.
A20: W3 Missions de lecture et de rédaction (M0, M1, M2, M6, M9) | B20: Développeur full-stack senior (externe) | C20: 14 | D20: 12 | E20: =C20*$B$6 | F20: =D20*$B$6 | G20: Premières missions livrées au pilote ; mesurent le coût du socle et du briefing.
A21: W4 Missions de coordination et d'inventaire (M7, M8, M11) | B21: Développeur full-stack senior (externe) | C21: 10 | D21: 8 | E21: =C21*$B$6 | F21: =D21*$B$6 | G21: Calendriers partagés, inventaire des abonnements, activation.
A22: W5 Missions à navigateur piloté (M3, M4, M10) | B22: Ingénieur IA / LLM (externe) | C22: 18 | D22: 16 | E22: =C22*$B$7 | F22: =D22*$B$7 | G22: Le chantier le plus risqué : sites sans API, CAPTCHA, conditions d'utilisation. Mesurer M3 et M4 avant d'investir davantage.
A23: W6 Mission de recherche (M5) | B23: Ingénieur IA / LLM (externe) | C23: 6 | D23: 5 | E23: =C23*$B$7 | F23: =D23*$B$7 | G23: Recherche, lecture de pages, synthèse chiffrée ; pas de réservation.
A24: W7 Conception UX : onboarding, écran de validation, journal, briefing | B24: Product designer UX/UI (externe) | C24: 12 | D24: 15 | E24: =C24*$B$8 | F24: =D24*$B$8 | G24: Maquettes puis tests avec les 10 pilotes.
A25: W8 Application web (PWA) : front, notifications, facturation Stripe | B25: Développeur full-stack senior (externe) | C25: 20 | D25: 18 | E25: =C25*$B$6 | F25: =D25*$B$6 | G25: Dépendance : W7 ; PWA plutôt que magasins d'applications pour le MVP.
A26: W9 Sécurité : pentest boîte grise (application et API) et contre-test | B26: Pentest application et API, jour d'auditeur (prestataire) | C26: 9 | D26: 10 | E26: =C26*$B$9 | F26: =D26*$B$9 | G26: Avant l'ouverture au-delà des 10 pilotes ; 8 000 à 12 000 € plus contre-test selon le marché 2026 ; devis à obtenir.
A27: W10 RGPD : AIPD, registre, politiques, charte agents | B27: Consultant RGPD / AIPD (externe) | C27: 5 | D27: 6 | E27: =C27*$B$10 | F27: =D27*$B$10 | G27: Avec Tiffany ; l'AIPD est obligatoire avant le pilote (lecture de courriels).
A28: W11 Vérification OAuth Google et évaluation CASA | B28: Fondateur, architecture et sécurité (Malik) | C28: 6 | D28: 6 | E28: =C28*$B$11 | F28: =D28*$B$11 | G28: Dossier, vidéo de démonstration, domaine vérifié, politique de confidentialité publiée ; délai externe de 4 à 8 semaines, à lancer en janvier.
A29: W12 Exploitation : hébergement, supervision, sauvegardes, astreinte | B29: Fondateur, exploitation et support (Isaac) | C29: 10 | D29: 10 | E29: =C29*$B$13 | F29: =D29*$B$13 | G29: Scaleway Paris ; procédures d'incident et de violation de données.
A30: W13 Recette, pilote, support des 10 pilotes, mesures | B30: Fondateur, produit et recette (Steve) | C30: 25 | D30: 25 | E30: =C30*$B$12 | F30: =D30*$B$12 | G30: Protocole de mesure des missions 1, 5 puis 3, 4 ; rapport de pilote pour la porte J+90.
A31: W14 Second développeur (variante Confort seulement) | B31: Développeur full-stack senior (externe) | C31: 0 | D31: 40 | E31: =C31*$B$6 | F31: =D31*$B$6 | G31: Parallélise W3 à W5 et W8 ; raccourcit le calendrier d'environ six semaines.
A32: Total jours et coût de main-d'œuvre externe | C32: =SUM(C17:C31) | D32: =SUM(D17:D31) | E32: =SUM(E17:E31) | F32: =SUM(F17:F31)
A33: dont jours des fondateurs (non facturés) | C33: =SUMIF($B$17:$B$31,"Fondateur*",C17:C31) | D33: =SUMIF($B$17:$B$31,"Fondateur*",D17:D31)
A35: Autres coûts du MVP (hors main-d'œuvre externe)
A36: Poste | B36: Base | C36: Lean (€ HT) | D36: Confort (€ HT) | G36: Source ou hypothèse
A37: API modèles et outils pendant la construction et le pilote (5 mois) | B37: 5 mois × 400 € | C37: 2000 | D37: 3000 | G37: Hypothèse : 10 pilotes × coût mensuel + tests d'ingénierie ; voir Synthèse.
A38: Hébergement et services pendant la construction (5 mois) | B38: 5 mois × 250 € | C38: 1250 | D38: 1500 | G38: Scaleway Paris, base de données gérée, stockage, supervision ; détail dans la réponse au cadrage.
A39: Évaluation de sécurité CASA niveau AL1 (laboratoire agréé, première année) | B39: forfait | C39: 1500 | D39: 2500 | G39: Marché 540 à 1 800 $ par an au niveau AL1 (TAC Security, Netsentries, Leviathan) ; renouvellement annuel ; vérification Google elle-même gratuite. Source : references prix et benchmarks, § infra 10.2.
A40: Juridique : statuts, pacte, CGV, politiques | B40: forfait | C40: 4000 | D40: 4000 | G40: Business plan Lean V1 (Finance).
A41: Tests utilisateurs et acquisition pilote | B41: forfait | C41: 5000 | D41: 5000 | G41: Business plan Lean V1 (Finance).
A42: Logiciels, outils de développement, observabilité | B42: 5 mois × 300 € | C42: 1500 | D42: 2000 | G42: Hypothèse.
A43: Nom de domaine, marque (recherche d'antériorité, dépôt INPI) | B43: forfait | C43: 1500 | D43: 1500 | G43: Hypothèse ; dépôt INPI une classe environ 190 € + recherche.
...

Sheet Tableau commun
A1: Tableau commun demandé par Finance
A2: Mission | priorité | scénario d'exécution | modèle IA | appels et outils | coût estimé HT | taux de réussite | risque | décision recommandée. Les coûts sont liés à l'onglet Missions.
A4: Mission | B4: Priorité | C4: Scénario d'exécution | D4: Modèle IA | E4: Appels et outils | F4: Coût estimé HT par exécution | G4: Coût mensuel Premium | H4: Taux de réussite (estimé, non mesuré) | I4: Risque principal | J4: Décision recommandée
A5: M0 Socle : tri quotidien des courriels et de l'agenda (partagé par M1, M2, M8, M9) | B5: Socle | C5: Lecture nocturne des courriels, de l'agenda et de Drive ; classement, résumés, entités en mémoire. | D5: Petit | E5: 1 appel petit modèle par nuit (≈ 20 k jetons) ; API Gmail, Agenda, Drive (gratuites) ; embeddings. | F5: =Missions!AB5 | G5: =Missions!AC5 | H5: =Missions!T5 | I5: Injection de prompt par un courriel : le socle ne doit jamais déclencher d'action. Volume de courriels très variable selon l'utilisateur. | J5: Construire en premier ; contenu des courriels traité comme données non fiables ; aucune capacité d'action.
A6: M1 Briefing quotidien | B6: 1 | C6: Composition matinale de 3 à 5 points à partir du socle. | D6: Moyen | E6: 1 appel moyen (≈ 8 k jetons, moitié en cache). | F6: =Missions!AB6 | G6: =Missions!AC6 | H6: =Missions!T6 | I6: Banalité : un briefing sans valeur perçue fait partir l'utilisateur. | J6: Mission d'habitude : livrer au pilote dès le jour 1 ; mesurer l'ouverture quotidienne.
A7: M2 Suivi des échéances personnelles | B7: 1 | C7: Extraction et confirmation des échéances, rappels J-30 et J-7. | D7: Petit puis moyen | E7: 1 appel petit + 1 appel moyen par échéance. | F7: =Missions!AB7 | G7: =Missions!AC7 | H7: =Missions!T7 | I7: Faux positifs (fausse échéance) et oublis ; aucune démarche officielle. | J7: Inclure ; rappel seulement ; taux de faux positifs à mesurer.
A8: M3 Prise de rendez-vous de service (garage, coiffeur, artisan) | B8: 2 | C8: Recherche de prestataires, créneaux, réservation en ligne par navigateur piloté après validation. | D8: Moyen, escalade frontière 5 % | E8: ≈ 15 appels moyens, 2 petits ; Places × 3 ; navigateur 8 min. | F8: =Missions!AB8 | G8: =Missions!AC8 | H8: =Missions!T8 | I8: Pas d'API chez la plupart des plateformes ; CAPTCHA et conditions d'utilisation ; échec en cours de parcours. | J8: Inclure sur un périmètre de plateformes testé ; au plafond de minutes, l'utilisateur termine lui-même.
A9: M4 Réservation de restaurant | B9: 2 | C9: Propositions puis réservation par navigateur piloté après validation. | D9: Moyen, escalade frontière 5 % | E9: ≈ 12 appels moyens, 2 petits ; Places × 4 ; navigateur 6 min ; API partenaire si accord TheFork ou Mozrest. | F9: =Missions!AB9 | G9: =Missions!AC9 | H9: =Missions!T9 | I9: Idem M3 ; double réservation si reprise mal gérée. | J9: Inclure ; idempotence des réservations ; mesurer dès le pilote (mission qui démontre la promesse).
A10: M5 Organisation d'un déplacement privé | B10: 2 | C10: Recherche, lecture de pages, programme à 2 ou 3 options chiffrées ; aucune réservation. | D10: Moyen, petit pour l'extraction | E10: 8 recherches, 10 lectures de page, 6 appels moyens, 4 petits. | F10: =Missions!AB10 | G10: =Missions!AC10 | H10: =Missions!T10 | I10: Qualité de la synthèse ; prix périmés ; Code du tourisme si réservation. | J10: Inclure sans réservation ; la mission la plus coûteuse en jetons, à mesurer en premier avec M1.
A11: M6 Brouillons de courriels personnels | B11: 1 | C11: Brouillon dans le ton de l'utilisateur, envoi après validation. | D11: Moyen | E11: 1 appel moyen. | F11: =Missions!AB11 | G11: =Missions!AC11 | H11: =Missions!T11 | I11: Ton inadapté ; envoi sans validation (interdit par le moteur de politique). | J11: Inclure ; mesurer le taux de brouillons envoyés sans modification.
A12: M7 Coordination de l'agenda familial | B12: 2 | C12: Détection des conflits d'agenda, proposition, modification après validation. | D12: Petit puis moyen | E12: 1 petit + 1 moyen ; API Agenda. | F12: =Missions!AB12 | G12: =Missions!AC12 | H12: =Missions!T12 | I12: Tiers concernés (conjoint, enfants) : validation à chaque fois. | J12: Inclure pour tester la cible famille ; profils multiples reportés.
A13: M8 Suivi des abonnements | B13: 3 | C13: Inventaire mensuel des abonnements, alertes, lettre de résiliation préparée. | D13: Petit puis moyen | E13: 1 petit + 1,5 moyen. | F13: =Missions!AB13 | G13: =Missions!AC13 | H13: =Missions!T13 | I13: Inventaire incomplet ; résiliation par prélèvement exclue. | J13: Inclure (faible coût, forte valeur perçue) ; pas d'accès bancaire.
A14: M9 Relances et engagements en attente | B14: 1 | C14: Liste des attentes, relance rédigée au bon moment, envoi après validation. | D14: Moyen | E14: 0,5 petit + 1 moyen. | F14: =Missions!AB14 | G14: =Missions!AC14 | H14: =Missions!T14 | I14: Relance inopportune ; doublon avec M6. | J14: Inclure ; fusionner l'interface avec M6.
A15: M10 Préparation d'un événement personnel | B15: 3 | C15: Rappel, idées, organisation, réservation éventuelle (réutilise M4). | D15: Moyen | E15: 3 moyens, 1 petit ; recherches × 3 ; Places ; navigateur 3 min. | F15: =Missions!AB15 | G15: =Missions!AC15 | H15: =Missions!T15 | I15: Faible fréquence, forte variabilité. | J15: Reporter après le pilote si M3 et M4 ne tiennent pas leurs mesures ; sinon inclure.
A16: M11 Activation : lecture initiale de la boîte et profil (une fois par nouvel abonné) | B16: Socle | C16: Lecture initiale de 12 mois de courriels en lot, profil de préférences confirmé par l'utilisateur. | D16: Petit en lot, moyen pour le profil | E16: ≈ 400 k jetons petit modèle en lot (tarif lot −50 %), embeddings, 1 appel moyen. | F16: =Missions!AB16 | G16: =Missions!AC16 | H16: =Missions!T16 | I16: Coût d'activation ; données particulières incidentes (santé, opinions) à détecter et ne pas conserver. | J16: Inclure avec filtrage des données particulières ; compter dans le CAC.
