Workbook

Sheet Lisez-moi
A1: Helium, modèle financier 36 mois, V1
A3: Objet | B3: Prévision mensuelle de trésorerie sur 36 mois pour le projet Helium (ex Super Majordome IA), HEC GEMM Group 4. Trois scénarios, économie unitaire, sensibilités, KPI et plan de financement.
A4: Statut | B4: Document de travail. Toutes les hypothèses sont non validées par des mesures (voir colonne Source de l'onglet Hypothèses). Aucun chiffre n'est une dépense engagée ni un financement obtenu.
A5: Préparé par | B5: Assistant IA Direction, à la demande du CEO (Malik), le 27 octobre 2026, pour Sébastien (Finance).
A6: Légende | B6: Texte bleu = entrée modifiable. Fond jaune = levier clé. Texte noir = formule. Texte vert = lien vers un autre onglet. Ne rien saisir dans les onglets Modèle et S01 à S10 en dehors de la ligne de chocs.
A7: Onglets | B7: Hypothèses (toutes les entrées, trois scénarios, sélecteur F3) · Économie unitaire (par offre, grilles de sensibilité) · Modèle Prudent / Central / Ambitieux (36 mois) · Synthèse (comparaison) · Tornade (sensibilités du Central) · S01 à S11 (copies du Central avec un choc) · KPI · Financement.
A8: Mécanique | B8: Abonnés : ouverture + acquisition payante (budget / CAC) + pilote + organique − churn. Revenus TTC → TVA → CA HT. Coûts variables = missions × coût par mission + hébergement + support. Trésorerie : encaissements TTC, coûts HT, TVA nette réglée le mois suivant, financement optionnel.
A9: Simplifications | B9: Mix par offre appliqué au total des abonnés. TVA récupérable sur tous les coûts externes (fournisseurs étrangers en autoliquidation). Pas d'impôt sur les sociétés (pertes), pas de CIR/CII, pas de délai de paiement fournisseurs. Développement MVP passé en charges.
A10: Sensibilités | B10: Onglet Tornade : Churn 5 % (churn × 1,67 (3 % → 5 %)) ; Churn 2 % (churn × 0,67 (3 % → 2 %)) ; CAC 240 € (CAC × 1,6) ; CAC 105 € (CAC × 0,7) ; Coût IA +67 % (coût par mission × 1,67 (0,18 → 0,30 €)) ; Coût IA −33 % (coût par mission × 0,67 (0,18 → 0,12 €)) ; Prix −20 % (prix × 0,8 (Premium 79 → 63 €)) ; Prix +20 % (prix × 1,2 (Premium 79 → 95 €)) ; Lancement +3 mois (retard de lancement de 3 mois) ; Coûts fixes +30 % (coûts fixes × 1,3) ; Churn 8 % (type app store) (churn × 2,67 (3 % → 8 %)).
A11: Contrôles effectués | B11: Recalcul complet sous LibreOffice, zéro erreur de formule ; mix = 100 % ; cohérence avec les ordres de grandeur Finance V3 (point bas central −173 k€, prudent −580 k€) ; hypothèses de coût IA, churn et CAC confrontées aux benchmarks publics d'octobre 2026 (sources dans la colonne G de l'onglet Hypothèses et dans l'analyse de marché).
A12: À faire par Finance | B12: Remplacer les hypothèses de coût par mission et de missions par mois par les mesures de Produit/Opérations ; remplacer CAC, conversion et churn par les cohortes du pilote ; saisir les devis MVP réels ; valider le régime de TVA et les dates d'encaissement.
A13: Sources internes | B13: 0 INBOX/BMC V2 ; 2 FINANCE/PREVISIONS (Business plan Lean V1, Registre des hypothèses, Acquisition et économie unitaire) ; 2 FINANCE/TRESORERIE (Synthèse V3) ; 2 FINANCE/FINANCEMENT (Stratégie V1) ; 4 VENTES (Synthèse exécutive, Objectifs et dashboard) ; 5 PRODUIT (Contribution marketing au cadrage MVP).

Sheet Hypothèses
A1: Hypothèses par scénario
A2: Cellules bleues = entrées modifiables. Colonne F = scénario actif (sélecteur en F3). Chaque ligne cite sa source ou dit qu'elle est une hypothèse.
E3: Scénario actif (1 = Prudent, 2 = Central, 3 = Ambitieux) | F3: 2
A5: Hypothèse | B5: Unité | C5: Prudent | D5: Central | E5: Ambitieux | F5: Actif | G5: Source / commentaire
A6: Calendrier
A7: Date de début du modèle (M1) | B7: date | C7: 46327 | D7: 46327 | E7: 46327 | F7: =INDEX(C7:E7,1,$F$3) | G7: Hypothèse de calendrier : M1 = novembre 2026. Modifiable.
A8: Mois de démarrage du pilote payant | B8: mois | C8: 4 | D8: 3 | E8: 3 | F8: =INDEX(C8:E8,1,$F$3) | G8: Plan Ventes 90 jours : 10 pilotes payants entre J31 et J60 (4 VENTES/2026 1027 01 Synthese executive).
A9: Taille de la cohorte pilote payante | B9: abonnés | C9: 10 | D9: 10 | E9: 10 | F9: =INDEX(C9:E9,1,$F$3) | G9: Même source. Les pilotes paient le prix public.
A10: Mois de lancement commercial | B10: mois | C10: 10 | D10: 7 | E10: 6 | F10: =INDEX(C10:E10,1,$F$3) | G10: Finance V3 : lancement M7 (central) / M10 (prudent). Source : 2 FINANCE/TRESORERIE/2026 1027 Synthese tresorerie V3.
A11: Prix et mix (TTC par mois)
A12: Prix Personal TTC | B12: €/mois | C12: 29 | D12: 29 | E12: 29 | F12: =INDEX(C12:E12,1,$F$3) | G12: BMC V2, hypothèse H01 non validée. À tester (Van Westendorp).
A13: Prix Premium TTC | B13: €/mois | C13: 79 | D13: 79 | E13: 79 | F13: =INDEX(C13:E13,1,$F$3) | G13: BMC V2, hypothèse H01 non validée.
A14: Prix Family TTC | B14: €/mois | C14: 129 | D14: 129 | E14: 129 | F14: =INDEX(C14:E14,1,$F$3) | G14: BMC V2, hypothèse H01 non validée.
A15: TVA | B15: % | C15: 0.2 | D15: 0.2 | E15: 0.2 | F15: =INDEX(C15:E15,1,$F$3) | G15: Taux normal France (hypothèse H02). Ventes B2C UE hors France : TVA du pays du client (OSS).
A16: Part Personal dans les abonnés | B16: % | C16: 0.3 | D16: 0.25 | E16: 0.2 | F16: =INDEX(C16:E16,1,$F$3) | G16: Hypothèse de mix. Aucune donnée observée.
A17: Part Premium | B17: % | C17: 0.55 | D17: 0.6 | E17: 0.6 | F17: =INDEX(C17:E17,1,$F$3) | G17: Hypothèse de mix.
A18: Part Family | B18: % | C18: 0.15 | D18: 0.15 | E18: 0.2 | F18: =INDEX(C18:E18,1,$F$3) | G18: Hypothèse de mix. Doit sommer à 100 % avec les deux lignes précédentes.
A19: Acquisition
A20: Budget d'acquisition mensuel, du lancement à M12 | B20: € HT/mois | C20: 2000 | D20: 3000 | E20: 4000 | F20: =INDEX(C20:E20,1,$F$3) | G20: Hypothèse. Finance V3 : 24 188 € d'acquisition en A1 (central).
A21: Budget d'acquisition mensuel, M13 à M24 | B21: € HT/mois | C21: 6000 | D21: 10000 | E21: 12000 | F21: =INDEX(C21:E21,1,$F$3) | G21: Hypothèse. Finance V3 : 121 688 € en A2.
A22: Budget d'acquisition mensuel, M25 à M36 | B22: € HT/mois | C22: 12000 | D22: 25000 | E22: 25000 | F22: =INDEX(C22:E22,1,$F$3) | G22: Hypothèse. Finance V3 : 340 275 € en A3.
A23: CAC (coût par abonné payant acquis) | B23: € | C23: 240 | D23: 150 | E23: 110 | F23: =INDEX(C23:E23,1,$F$3) | G23: Hypothèse H04 (150 €) et prudent (240 €). Benchmarks : CPI iOS 4,70 $ (Adapty 2026) / conversion téléchargement → payant 2 % (RevenueCat 2026) ≈ 235 $ par abonné payant en acquisition payante ; 44 $ avec paywall et essai. Réseau et parrainage visés pour rester sous 150 €. Non mesuré.
A24: Acquisition organique (parrainage), % de la base par mois | B24: % | C24: 0.01 | D24: 0.02 | E24: 0.025 | F24: =INDEX(C24:E24,1,$F$3) | G24: Hypothèse. À mesurer pendant le pilote.
A25: Rétention et encaissement
A26: Churn mensuel (résiliations / abonnés début de mois) | B26: % | C26: 0.06 | D26: 0.03 | E26: 0.025 | F26: =INDEX(C26:E26,1,$F$3) | G26: Hypothèse H05 (3 %). Benchmarks : Recurly juillet 2026, ARPU 10 à 25 $ : 4,3 % par mois ; ProfitWell, ARPU 25 à 50 $ : 6,9 % par mois ; RevenueCat 2026, applications IA en plan mensuel : 6 % de rétention à 12 mois (churn précoce très élevé). Prudent fixé à 6 %. Non mesuré.
A27: Impayés, % de la facturation | B27: % | C27: 0.02 | D27: 0.01 | E27: 0.005 | F27: =INDEX(C27:E27,1,$F$3) | G27: Scénario prudent Finance : 2 %.
A28: Frais de paiement, % du montant encaissé | B28: % | C28: 0.015 | D28: 0.015 | E28: 0.015 | F28: =INDEX(C28:E28,1,$F$3) | G28: Ordre de grandeur Stripe cartes EEE : 1,5 % + 0,25 €. À vérifier sur la grille en vigueur.
A29: Frais de paiement fixes par transaction | B29: € | C29: 0.25 | D29: 0.25 | E29: 0.25 | F29: =INDEX(C29:E29,1,$F$3) | G29: Idem.
A30: Coûts variables (HT, par abonné et par mois)
A31: Missions exécutées par mois, Personal | B31: missions | C31: 20 | D31: 20 | E31: 20 | F31: =INDEX(C31:E31,1,$F$3) | G31: Hypothèse d'usage. À mesurer (demande de cadrage Finance → Produit).
A32: Missions exécutées par mois, Premium | B32: missions | C32: 60 | D32: 60 | E32: 60 | F32: =INDEX(C32:E32,1,$F$3) | G32: Hypothèse : 2 missions par jour ouvré.
A33: Missions exécutées par mois, Family | B33: missions | C33: 90 | D33: 90 | E33: 90 | F33: =INDEX(C33:E33,1,$F$3) | G33: Hypothèse.
A34: Coût IA et outils par mission (tokens, API, reprises) | B34: € HT | C34: 0.3 | D34: 0.18 | E34: 0.12 | F34: =INDEX(C34:E34,1,$F$3) | G34: Hypothèse conservée au-dessus de l'estimation ascendante : le classeur Technique/Helium_Cout_par_mission_V1.xlsx (28/10/2026, prix publics Mistral, Anthropic via Bedrock UE, Brave, Places, Browserbase) donne environ 0,07 € par mission visible pour un abonné Premium, socle nocturne réparti, et environ 1 € pour une prise de rendez-vous par navigateur piloté (support humain compris). 0,18 € (central) couvre 2,5 fois l'estimation ; 0,30 € (prudent) est le seuil au-delà duquel le plan prévoit limites d'usage et test de prix. Référence externe : tau2-bench 0,26 à 0,49 $ par trajectoire (classe Sonnet). À remplacer par les mesures des missions 1 et 5 (3 décembre) puis 3 et 4 (19 décembre).
A35: Hébergement, stockage, connecteurs | B35: € HT | C35: 2 | D35: 1.5 | E35: 1 | F35: =INDEX(C35:E35,1,$F$3) | G35: Hypothèse.
A36: Support humain (minutes × coût horaire) | B36: € HT | C36: 5 | D36: 3 | E36: 2 | F36: =INDEX(C36:E36,1,$F$3) | G36: Hypothèse.
A37: Coûts fixes (HT, par mois)
A38: Nombre de fondateurs rémunérés à partir du mois ci-dessous | B38: personnes | C38: 2 | D38: 2 | E38: 2 | F38: =INDEX(C38:E38,1,$F$3) | G38: Hypothèse Finance : fondateurs non rémunérés M1 à M12.
A39: Premier mois de rémunération des fondateurs | B39: mois | C39: 13 | D39: 13 | E39: 13 | F39: =INDEX(C39:E39,1,$F$3) | G39: Idem.
A40: Coût chargé mensuel par fondateur rémunéré | B40: € HT | C40: 5500 | D40: 5000 | E40: 5000 | F40: =INDEX(C40:E40,1,$F$3) | G40: Hypothèse modeste (≈ 3 000 € nets + charges, régime assimilé salarié).
A41: Embauche 1 (growth / customer success), premier mois | B41: mois | C41: 16 | D41: 13 | E41: 10 | F41: =INDEX(C41:E41,1,$F$3) | G41: Plan Ventes : growth 0,5 ETP puis customer success.
...

Sheet Économie unitaire
A1: Économie unitaire (scénario actif)
A2: Par abonné et par mois, HT. Référence : colonne Actif de l'onglet Hypothèses.
A4: Ligne | B4: Personal | C4: Premium | D4: Family | E4: Mix pondéré
A5: Prix TTC | B5: =Hypothèses!$F$12 | C5: =Hypothèses!$F$13 | D5: =Hypothèses!$F$14 | E5: =B5*Hypothèses!$F$16+C5*Hypothèses!$F$17+D5*Hypothèses!$F$18
A6: Prix HT | B6: =Hypothèses!$F$12/(1+Hypothèses!$F$15) | C6: =Hypothèses!$F$13/(1+Hypothèses!$F$15) | D6: =Hypothèses!$F$14/(1+Hypothèses!$F$15) | E6: =B6*Hypothèses!$F$16+C6*Hypothèses!$F$17+D6*Hypothèses!$F$18
A7: Missions par mois | B7: =Hypothèses!$F$31 | C7: =Hypothèses!$F$32 | D7: =Hypothèses!$F$33 | E7: =B7*Hypothèses!$F$16+C7*Hypothèses!$F$17+D7*Hypothèses!$F$18
A8: Coût IA et outils | B8: =Hypothèses!$F$31*Hypothèses!$F$34 | C8: =Hypothèses!$F$32*Hypothèses!$F$34 | D8: =Hypothèses!$F$33*Hypothèses!$F$34 | E8: =B8*Hypothèses!$F$16+C8*Hypothèses!$F$17+D8*Hypothèses!$F$18
A9: Hébergement | B9: =Hypothèses!$F$35 | C9: =Hypothèses!$F$35 | D9: =Hypothèses!$F$35 | E9: =B9*Hypothèses!$F$16+C9*Hypothèses!$F$17+D9*Hypothèses!$F$18
A10: Support | B10: =Hypothèses!$F$36 | C10: =Hypothèses!$F$36 | D10: =Hypothèses!$F$36 | E10: =B10*Hypothèses!$F$16+C10*Hypothèses!$F$17+D10*Hypothèses!$F$18
A11: Frais de paiement | B11: =Hypothèses!$F$12*(1-Hypothèses!$F$27)*Hypothèses!$F$28+Hypothèses!$F$29 | C11: =Hypothèses!$F$13*(1-Hypothèses!$F$27)*Hypothèses!$F$28+Hypothèses!$F$29 | D11: =Hypothèses!$F$14*(1-Hypothèses!$F$27)*Hypothèses!$F$28+Hypothèses!$F$29 | E11: =B11*Hypothèses!$F$16+C11*Hypothèses!$F$17+D11*Hypothèses!$F$18
A12: Impayés (HT) | B12: =Hypothèses!$F$12*Hypothèses!$F$27/(1+Hypothèses!$F$15) | C12: =Hypothèses!$F$13*Hypothèses!$F$27/(1+Hypothèses!$F$15) | D12: =Hypothèses!$F$14*Hypothèses!$F$27/(1+Hypothèses!$F$15) | E12: =B12*Hypothèses!$F$16+C12*Hypothèses!$F$17+D12*Hypothèses!$F$18
A13: Contribution par abonné et par mois | B13: =B6-B8-B9-B10-B11-B12 | C13: =C6-C8-C9-C10-C11-C12 | D13: =D6-D8-D9-D10-D11-D12 | E13: =E6-E8-E9-E10-E11-E12
A14: Marge variable (% du prix HT) | B14: =IF(B6>0,B13/B6,0) | C14: =IF(C6>0,C13/C6,0) | D14: =IF(D6>0,D13/D6,0) | E14: =IF(E6>0,E13/E6,0)
A15: Payback du CAC (mois) | B15: =IF(B13>0,Hypothèses!$F$23/B13,0) | C15: =IF(C13>0,Hypothèses!$F$23/C13,0) | D15: =IF(D13>0,Hypothèses!$F$23/D13,0) | E15: =IF(E13>0,Hypothèses!$F$23/E13,0)
A16: LTV contributive simplifiée (contribution / churn) | B16: =IF(Hypothèses!$F$26>0,B13/Hypothèses!$F$26,0) | C16: =IF(Hypothèses!$F$26>0,C13/Hypothèses!$F$26,0) | D16: =IF(Hypothèses!$F$26>0,D13/Hypothèses!$F$26,0) | E16: =IF(Hypothèses!$F$26>0,E13/Hypothèses!$F$26,0)
A17: LTV / CAC | B17: =IF(Hypothèses!$F$23>0,B16/Hypothèses!$F$23,0) | C17: =IF(Hypothèses!$F$23>0,C16/Hypothèses!$F$23,0) | D17: =IF(Hypothèses!$F$23>0,D16/Hypothèses!$F$23,0) | E17: =IF(Hypothèses!$F$23>0,E16/Hypothèses!$F$23,0)
A20: Grille LTV / CAC, abonné Premium : churn mensuel (lignes) × CAC (colonnes)
A21: Churn \ CAC | B21: 100 | C21: 150 | D21: 200 | E21: 250 | F21: 300 | G21: 400
A22: 0.02 | B22: =IF(AND($A22>0,B$21>0),($C$13/$A22)/B$21,0) | C22: =IF(AND($A22>0,C$21>0),($C$13/$A22)/C$21,0) | D22: =IF(AND($A22>0,D$21>0),($C$13/$A22)/D$21,0) | E22: =IF(AND($A22>0,E$21>0),($C$13/$A22)/E$21,0) | F22: =IF(AND($A22>0,F$21>0),($C$13/$A22)/F$21,0) | G22: =IF(AND($A22>0,G$21>0),($C$13/$A22)/G$21,0)
A23: 0.03 | B23: =IF(AND($A23>0,B$21>0),($C$13/$A23)/B$21,0) | C23: =IF(AND($A23>0,C$21>0),($C$13/$A23)/C$21,0) | D23: =IF(AND($A23>0,D$21>0),($C$13/$A23)/D$21,0) | E23: =IF(AND($A23>0,E$21>0),($C$13/$A23)/E$21,0) | F23: =IF(AND($A23>0,F$21>0),($C$13/$A23)/F$21,0) | G23: =IF(AND($A23>0,G$21>0),($C$13/$A23)/G$21,0)
A24: 0.04 | B24: =IF(AND($A24>0,B$21>0),($C$13/$A24)/B$21,0) | C24: =IF(AND($A24>0,C$21>0),($C$13/$A24)/C$21,0) | D24: =IF(AND($A24>0,D$21>0),($C$13/$A24)/D$21,0) | E24: =IF(AND($A24>0,E$21>0),($C$13/$A24)/E$21,0) | F24: =IF(AND($A24>0,F$21>0),($C$13/$A24)/F$21,0) | G24: =IF(AND($A24>0,G$21>0),($C$13/$A24)/G$21,0)
A25: 0.05 | B25: =IF(AND($A25>0,B$21>0),($C$13/$A25)/B$21,0) | C25: =IF(AND($A25>0,C$21>0),($C$13/$A25)/C$21,0) | D25: =IF(AND($A25>0,D$21>0),($C$13/$A25)/D$21,0) | E25: =IF(AND($A25>0,E$21>0),($C$13/$A25)/E$21,0) | F25: =IF(AND($A25>0,F$21>0),($C$13/$A25)/F$21,0) | G25: =IF(AND($A25>0,G$21>0),($C$13/$A25)/G$21,0)
A26: 0.07 | B26: =IF(AND($A26>0,B$21>0),($C$13/$A26)/B$21,0) | C26: =IF(AND($A26>0,C$21>0),($C$13/$A26)/C$21,0) | D26: =IF(AND($A26>0,D$21>0),($C$13/$A26)/D$21,0) | E26: =IF(AND($A26>0,E$21>0),($C$13/$A26)/E$21,0) | F26: =IF(AND($A26>0,F$21>0),($C$13/$A26)/F$21,0) | G26: =IF(AND($A26>0,G$21>0),($C$13/$A26)/G$21,0)
A27: 0.1 | B27: =IF(AND($A27>0,B$21>0),($C$13/$A27)/B$21,0) | C27: =IF(AND($A27>0,C$21>0),($C$13/$A27)/C$21,0) | D27: =IF(AND($A27>0,D$21>0),($C$13/$A27)/D$21,0) | E27: =IF(AND($A27>0,E$21>0),($C$13/$A27)/E$21,0) | F27: =IF(AND($A27>0,F$21>0),($C$13/$A27)/F$21,0) | G27: =IF(AND($A27>0,G$21>0),($C$13/$A27)/G$21,0)
A30: Grille contribution Premium (€ HT/mois) : coût par mission (lignes) × missions par mois (colonnes)
A31: Coût/mission \ Missions | B31: 30 | C31: 45 | D31: 60 | E31: 90 | F31: 120
A32: 0.08 | B32: =$C$6-$A32*B$31-$C$9-$C$10-$C$11-$C$12 | C32: =$C$6-$A32*C$31-$C$9-$C$10-$C$11-$C$12 | D32: =$C$6-$A32*D$31-$C$9-$C$10-$C$11-$C$12 | E32: =$C$6-$A32*E$31-$C$9-$C$10-$C$11-$C$12 | F32: =$C$6-$A32*F$31-$C$9-$C$10-$C$11-$C$12
A33: 0.12 | B33: =$C$6-$A33*B$31-$C$9-$C$10-$C$11-$C$12 | C33: =$C$6-$A33*C$31-$C$9-$C$10-$C$11-$C$12 | D33: =$C$6-$A33*D$31-$C$9-$C$10-$C$11-$C$12 | E33: =$C$6-$A33*E$31-$C$9-$C$10-$C$11-$C$12 | F33: =$C$6-$A33*F$31-$C$9-$C$10-$C$11-$C$12
A34: 0.18 | B34: =$C$6-$A34*B$31-$C$9-$C$10-$C$11-$C$12 | C34: =$C$6-$A34*C$31-$C$9-$C$10-$C$11-$C$12 | D34: =$C$6-$A34*D$31-$C$9-$C$10-$C$11-$C$12 | E34: =$C$6-$A34*E$31-$C$9-$C$10-$C$11-$C$12 | F34: =$C$6-$A34*F$31-$C$9-$C$10-$C$11-$C$12
A35: 0.25 | B35: =$C$6-$A35*B$31-$C$9-$C$10-$C$11-$C$12 | C35: =$C$6-$A35*C$31-$C$9-$C$10-$C$11-$C$12 | D35: =$C$6-$A35*D$31-$C$9-$C$10-$C$11-$C$12 | E35: =$C$6-$A35*E$31-$C$9-$C$10-$C$11-$C$12 | F35: =$C$6-$A35*F$31-$C$9-$C$10-$C$11-$C$12
A36: 0.35 | B36: =$C$6-$A36*B$31-$C$9-$C$10-$C$11-$C$12 | C36: =$C$6-$A36*C$31-$C$9-$C$10-$C$11-$C$12 | D36: =$C$6-$A36*D$31-$C$9-$C$10-$C$11-$C$12 | E36: =$C$6-$A36*E$31-$C$9-$C$10-$C$11-$C$12 | F36: =$C$6-$A36*F$31-$C$9-$C$10-$C$11-$C$12
A37: 0.5 | B37: =$C$6-$A37*B$31-$C$9-$C$10-$C$11-$C$12 | C37: =$C$6-$A37*C$31-$C$9-$C$10-$C$11-$C$12 | D37: =$C$6-$A37*D$31-$C$9-$C$10-$C$11-$C$12 | E37: =$C$6-$A37*E$31-$C$9-$C$10-$C$11-$C$12 | F37: =$C$6-$A37*F$31-$C$9-$C$10-$C$11-$C$12

Sheet Modèle Prudent
A1: Modèle Prudent (36 mois)
A2: Flux en € HT sauf mention TTC. Formules vivantes ; ne saisir que dans l'onglet Hypothèses et la ligne de chocs ci-dessous.
A3: Chocs de sensibilité (1 = aucun ; retard en mois) | C3: Prix × | D3: Churn × | E3: CAC × | F3: Coût IA × | G3: Coûts fixes × | H3: Retard lancement (mois)
C4: 1 | D4: 1 | E4: 1 | F4: 1 | G4: 1 | H4: 0
A5: Mois de lancement effectif | B5: =Hypothèses!$C$10+$H$4
A6: Ligne | B6: Unité | C6: M1 | D6: M2 | E6: M3 | F6: M4 | G6: M5 | H6: M6 | I6: M7 | J6: M8 | K6: M9 | L6: M10 | M6: M11 | N6: M12 | O6: M13 | P6: M14 | Q6: M15 | R6: M16 | S6: M17 | T6: M18 | U6: M19 | V6: M20 | W6: M21 | X6: M22 | Y6: M23 | Z6: M24 | AA6: M25 | AB6: M26 | AC6: M27 | AD6: M28 | AE6: M29 | AF6: M30 | AG6: M31 | AH6: M32 | AI6: M33 | AJ6: M34 | AK6: M35 | AL6: M36 | AN6: Année 1 | AO6: Année 2 | AP6: Année 3
A7: Mois | B7: n° | C7: 1 | D7: 2 | E7: 3 | F7: 4 | G7: 5 | H7: 6 | I7: 7 | J7: 8 | K7: 9 | L7: 10 | M7: 11 | N7: 12 | O7: 13 | P7: 14 | Q7: 15 | R7: 16 | S7: 17 | T7: 18 | U7: 19 | V7: 20 | W7: 21 | X7: 22 | Y7: 23 | Z7: 24 | AA7: 25 | AB7: 26 | AC7: 27 | AD7: 28 | AE7: 29 | AF7: 30 | AG7: 31 | AH7: 32 | AI7: 33 | AJ7: 34 | AK7: 35 | AL7: 36
A8: Date | C8: =EDATE(Hypothèses!$C$7,C7-1) | D8: =EDATE(Hypothèses!$C$7,D7-1) | E8: =EDATE(Hypothèses!$C$7,E7-1) | F8: =EDATE(Hypothèses!$C$7,F7-1) | G8: =EDATE(Hypothèses!$C$7,G7-1) | H8: =EDATE(Hypothèses!$C$7,H7-1) | I8: =EDATE(Hypothèses!$C$7,I7-1) | J8: =EDATE(Hypothèses!$C$7,J7-1) | ... AL8: =EDATE(Hypothèses!$C$7,AL7-1)
A9: Lancé ? (1 = oui) | B9: 0/1 | C9: =IF(C7>=$B$5,1,0) | D9: =IF(D7>=$B$5,1,0) | E9: =IF(E7>=$B$5,1,0) | F9: =IF(F7>=$B$5,1,0) | G9: =IF(G7>=$B$5,1,0) | H9: =IF(H7>=$B$5,1,0) | I9: =IF(I7>=$B$5,1,0) | J9: =IF(J7>=$B$5,1,0) | ... AL9: =IF(AL7>=$B$5,1,0)
A10: Pilote en cours ? (1 = oui) | B10: 0/1 | C10: =IF(AND(C7>=Hypothèses!$C$8,C7<$B$5),1,0) | D10: =IF(AND(D7>=Hypothèses!$C$8,D7<$B$5),1,0) | E10: =IF(AND(E7>=Hypothèses!$C$8,E7<$B$5),1,0) | F10: =IF(AND(F7>=Hypothèses!$C$8,F7<$B$5),1,0) | G10: =IF(AND(G7>=Hypothèses!$C$8,G7<$B$5),1,0) | H10: =IF(AND(H7>=Hypothèses!$C$8,H7<$B$5),1,0) | I10: =IF(AND(I7>=Hypothèses!$C$8,I7<$B$5),1,0) | J10: =IF(AND(J7>=Hypothèses!$C$8,J7<$B$5),1,0) | ... AL10: =IF(AND(AL7>=Hypothèses!$C$8,AL7<$B$5),1,0)
A11: Budget d'acquisition du mois | B11: € HT | C11: =IF(C9=1,IF(C7<=12,Hypothèses!$C$20,IF(C7<=24,Hypothèses!$C$21,Hypothèses!$C$22)),0) | D11: =IF(D9=1,IF(D7<=12,Hypothèses!$C$20,IF(D7<=24,Hypothèses!$C$21,Hypothèses!$C$22)),0) | E11: =IF(E9=1,IF(E7<=12,Hypothèses!$C$20,IF(E7<=24,Hypothèses!$C$21,Hypothèses!$C$22)),0) | F11: =IF(F9=1,IF(F7<=12,Hypothèses!$C$20,IF(F7<=24,Hypothèses!$C$21,Hypothèses!$C$22)),0) | G11: =IF(G9=1,IF(G7<=12,Hypothèses!$C$20,IF(G7<=24,Hypothèses!$C$21,Hypothèses!$C$22)),0) | H11: =IF(H9=1,IF(H7<=12,Hypothèses!$C$20,IF(H7<=24,Hypothèses!$C$21,Hypothèses!$C$22)),0) | I11: =IF(I9=1,IF(I7<=12,Hypothèses!$C$20,IF(I7<=24,Hypothèses!$C$21,Hypothèses!$C$22)),0) | J11: =IF(J9=1,IF(J7<=12,Hypothèses!$C$20,IF(J7<=24,Hypothèses!$C$21,Hypothèses!$C$22)),0) | ... AL11: =IF(AL9=1,IF(AL7<=12,Hypothèses!$C$20,IF(AL7<=24,Hypothèses!$C$21,Hypothèses!$C$22)),0) | AN11: =SUM(C11:N11) | AO11: =SUM(O11:Z11) | AP11: =SUM(AA11:AL11)
A12: Abonnés
A13: Abonnés en début de mois | B13: abonnés | C13: =0 | D13: =C18 | E13: =D18 | F13: =E18 | G13: =F18 | H13: =G18 | I13: =H18 | J13: =I18 | K13: =J18 | ... AL13: =AK18
A14: Nouveaux abonnés par acquisition payante | B14: abonnés | C14: =C11/(Hypothèses!$C$23*$E$4) | D14: =D11/(Hypothèses!$C$23*$E$4) | E14: =E11/(Hypothèses!$C$23*$E$4) | F14: =F11/(Hypothèses!$C$23*$E$4) | G14: =G11/(Hypothèses!$C$23*$E$4) | H14: =H11/(Hypothèses!$C$23*$E$4) | I14: =I11/(Hypothèses!$C$23*$E$4) | J14: =J11/(Hypothèses!$C$23*$E$4) | ... AL14: =AL11/(Hypothèses!$C$23*$E$4) | AN14: =SUM(C14:N14) | AO14: =SUM(O14:Z14) | AP14: =SUM(AA14:AL14)
A15: Nouveaux abonnés pilote | B15: abonnés | C15: =IF(C7=Hypothèses!$C$8,Hypothèses!$C$9,0) | D15: =IF(D7=Hypothèses!$C$8,Hypothèses!$C$9,0) | E15: =IF(E7=Hypothèses!$C$8,Hypothèses!$C$9,0) | F15: =IF(F7=Hypothèses!$C$8,Hypothèses!$C$9,0) | G15: =IF(G7=Hypothèses!$C$8,Hypothèses!$C$9,0) | H15: =IF(H7=Hypothèses!$C$8,Hypothèses!$C$9,0) | I15: =IF(I7=Hypothèses!$C$8,Hypothèses!$C$9,0) | J15: =IF(J7=Hypothèses!$C$8,Hypothèses!$C$9,0) | ... AL15: =IF(AL7=Hypothèses!$C$8,Hypothèses!$C$9,0) | AN15: =SUM(C15:N15) | AO15: =SUM(O15:Z15) | AP15: =SUM(AA15:AL15)
A16: Nouveaux abonnés organiques (parrainage) | B16: abonnés | C16: =C9*C13*Hypothèses!$C$24 | D16: =D9*D13*Hypothèses!$C$24 | E16: =E9*E13*Hypothèses!$C$24 | F16: =F9*F13*Hypothèses!$C$24 | G16: =G9*G13*Hypothèses!$C$24 | H16: =H9*H13*Hypothèses!$C$24 | I16: =I9*I13*Hypothèses!$C$24 | J16: =J9*J13*Hypothèses!$C$24 | ... AL16: =AL9*AL13*Hypothèses!$C$24 | AN16: =SUM(C16:N16) | AO16: =SUM(O16:Z16) | AP16: =SUM(AA16:AL16)
A17: Résiliations | B17: abonnés | C17: =C13*Hypothèses!$C$26*$D$4 | D17: =D13*Hypothèses!$C$26*$D$4 | E17: =E13*Hypothèses!$C$26*$D$4 | F17: =F13*Hypothèses!$C$26*$D$4 | G17: =G13*Hypothèses!$C$26*$D$4 | H17: =H13*Hypothèses!$C$26*$D$4 | I17: =I13*Hypothèses!$C$26*$D$4 | J17: =J13*Hypothèses!$C$26*$D$4 | ... AL17: =AL13*Hypothèses!$C$26*$D$4 | AN17: =SUM(C17:N17) | AO17: =SUM(O17:Z17) | AP17: =SUM(AA17:AL17)
A18: Abonnés en fin de mois | B18: abonnés | C18: =C13+C14+C15+C16-C17 | D18: =D13+D14+D15+D16-D17 | E18: =E13+E14+E15+E16-E17 | F18: =F13+F14+F15+F16-F17 | G18: =G13+G14+G15+G16-G17 | H18: =H13+H14+H15+H16-H17 | I18: =I13+I14+I15+I16-I17 | J18: =J13+J14+J15+J16-J17 | ... AL18: =AL13+AL14+AL15+AL16-AL17 | AN18: =N18 | AO18: =Z18 | AP18: =AL18
A19: dont Personal | B19: abonnés | C19: =C18*Hypothèses!$C$16 | D19: =D18*Hypothèses!$C$16 | E19: =E18*Hypothèses!$C$16 | F19: =F18*Hypothèses!$C$16 | G19: =G18*Hypothèses!$C$16 | H19: =H18*Hypothèses!$C$16 | I19: =I18*Hypothèses!$C$16 | J19: =J18*Hypothèses!$C$16 | ... AL19: =AL18*Hypothèses!$C$16 | AN19: =N19 | AO19: =Z19 | AP19: =AL19
A20: dont Premium | B20: abonnés | C20: =C18*Hypothèses!$C$17 | D20: =D18*Hypothèses!$C$17 | E20: =E18*Hypothèses!$C$17 | F20: =F18*Hypothèses!$C$17 | G20: =G18*Hypothèses!$C$17 | H20: =H18*Hypothèses!$C$17 | I20: =I18*Hypothèses!$C$17 | J20: =J18*Hypothèses!$C$17 | ... AL20: =AL18*Hypothèses!$C$17 | AN20: =N20 | AO20: =Z20 | AP20: =AL20
A21: dont Family | B21: abonnés | C21: =C18*Hypothèses!$C$18 | D21: =D18*Hypothèses!$C$18 | E21: =E18*Hypothèses!$C$18 | F21: =F18*Hypothèses!$C$18 | G21: =G18*Hypothèses!$C$18 | H21: =H18*Hypothèses!$C$18 | I21: =I18*Hypothèses!$C$18 | J21: =J18*Hypothèses!$C$18 | ... AL21: =AL18*Hypothèses!$C$18 | AN21: =N21 | AO21: =Z21 | AP21: =AL21
A22: Revenus
A23: Facturation Personal TTC | B23: € TTC | C23: =C19*Hypothèses!$C$12*$C$4 | D23: =D19*Hypothèses!$C$12*$C$4 | E23: =E19*Hypothèses!$C$12*$C$4 | F23: =F19*Hypothèses!$C$12*$C$4 | G23: =G19*Hypothèses!$C$12*$C$4 | H23: =H19*Hypothèses!$C$12*$C$4 | I23: =I19*Hypothèses!$C$12*$C$4 | J23: =J19*Hypothèses!$C$12*$C$4 | ... AL23: =AL19*Hypothèses!$C$12*$C$4 | AN23: =SUM(C23:N23) | AO23: =SUM(O23:Z23) | AP23: =SUM(AA23:AL23)
A24: Facturation Premium TTC | B24: € TTC | C24: =C20*Hypothèses!$C$13*$C$4 | D24: =D20*Hypothèses!$C$13*$C$4 | E24: =E20*Hypothèses!$C$13*$C$4 | F24: =F20*Hypothèses!$C$13*$C$4 | G24: =G20*Hypothèses!$C$13*$C$4 | H24: =H20*Hypothèses!$C$13*$C$4 | I24: =I20*Hypothèses!$C$13*$C$4 | J24: =J20*Hypothèses!$C$13*$C$4 | ... AL24: =AL20*Hypothèses!$C$13*$C$4 | AN24: =SUM(C24:N24) | AO24: =SUM(O24:Z24) | AP24: =SUM(AA24:AL24)
A25: Facturation Family TTC | B25: € TTC | C25: =C21*Hypothèses!$C$14*$C$4 | D25: =D21*Hypothèses!$C$14*$C$4 | E25: =E21*Hypothèses!$C$14*$C$4 | F25: =F21*Hypothèses!$C$14*$C$4 | G25: =G21*Hypothèses!$C$14*$C$4 | H25: =H21*Hypothèses!$C$14*$C$4 | I25: =I21*Hypothèses!$C$14*$C$4 | J25: =J21*Hypothèses!$C$14*$C$4 | ... AL25: =AL21*Hypothèses!$C$14*$C$4 | AN25: =SUM(C25:N25) | AO25: =SUM(O25:Z25) | AP25: =SUM(AA25:AL25)
A26: Facturation totale TTC (MRR TTC) | B26: € TTC | C26: =C23+C24+C25 | D26: =D23+D24+D25 | E26: =E23+E24+E25 | F26: =F23+F24+F25 | G26: =G23+G24+G25 | H26: =H23+H24+H25 | I26: =I23+I24+I25 | J26: =J23+J24+J25 | ... AL26: =AL23+AL24+AL25 | AN26: =SUM(C26:N26) | AO26: =SUM(O26:Z26) | AP26: =SUM(AA26:AL26)
A27: TVA collectée | B27: € | C27: =C26*Hypothèses!$C$15/(1+Hypothèses!$C$15) | D27: =D26*Hypothèses!$C$15/(1+Hypothèses!$C$15) | E27: =E26*Hypothèses!$C$15/(1+Hypothèses!$C$15) | F27: =F26*Hypothèses!$C$15/(1+Hypothèses!$C$15) | G27: =G26*Hypothèses!$C$15/(1+Hypothèses!$C$15) | H27: =H26*Hypothèses!$C$15/(1+Hypothèses!$C$15) | I27: =I26*Hypothèses!$C$15/(1+Hypothèses!$C$15) | J27: =J26*Hypothèses!$C$15/(1+Hypothèses!$C$15) | ... AL27: =AL26*Hypothèses!$C$15/(1+Hypothèses!$C$15) | AN27: =SUM(C27:N27) | AO27: =SUM(O27:Z27) | AP27: =SUM(AA27:AL27)
A28: Chiffre d'affaires HT | B28: € HT | C28: =C26-C27 | D28: =D26-D27 | E28: =E26-E27 | F28: =F26-F27 | G28: =G26-G27 | H28: =H26-H27 | I28: =I26-I27 | J28: =J26-J27 | ... AL28: =AL26-AL27 | AN28: =SUM(C28:N28) | AO28: =SUM(O28:Z28) | AP28: =SUM(AA28:AL28)
A29: Impayés (TTC) | B29: € TTC | C29: =C26*Hypothèses!$C$27 | D29: =D26*Hypothèses!$C$27 | E29: =E26*Hypothèses!$C$27 | F29: =F26*Hypothèses!$C$27 | G29: =G26*Hypothèses!$C$27 | H29: =H26*Hypothèses!$C$27 | I29: =I26*Hypothèses!$C$27 | J29: =J26*Hypothèses!$C$27 | ... AL29: =AL26*Hypothèses!$C$27 | AN29: =SUM(C29:N29) | AO29: =SUM(O29:Z29) | AP29: =SUM(AA29:AL29)
A30: Frais de paiement | B30: € | C30: =(C26-C29)*Hypothèses!$C$28+C18*Hypothèses!$C$29 | D30: =(D26-D29)*Hypothèses!$C$28+D18*Hypothèses!$C$29 | E30: =(E26-E29)*Hypothèses!$C$28+E18*Hypothèses!$C$29 | F30: =(F26-F29)*Hypothèses!$C$28+F18*Hypothèses!$C$29 | G30: =(G26-G29)*Hypothèses!$C$28+G18*Hypothèses!$C$29 | H30: =(H26-H29)*Hypothèses!$C$28+H18*Hypothèses!$C$29 | I30: =(I26-I29)*Hypothèses!$C$28+I18*Hypothèses!$C$29 | J30: =(J26-J29)*Hypothèses!$C$28+J18*Hypothèses!$C$29 | ... AL30: =(AL26-AL29)*Hypothèses!$C$28+AL18*Hypothèses!$C$29 | AN30: =SUM(C30:N30) | AO30: =SUM(O30:Z30) | AP30: =SUM(AA30:AL30)
A31: Encaissements nets TTC | B31: € TTC | C31: =C26-C29-C30 | D31: =D26-D29-D30 | E31: =E26-E29-E30 | F31: =F26-F29-F30 | G31: =G26-G29-G30 | H31: =H26-H29-H30 | I31: =I26-I29-I30 | J31: =J26-J29-J30 | ... AL31: =AL26-AL29-AL30 | AN31: =SUM(C31:N31) | AO31: =SUM(O31:Z31) | AP31: =SUM(AA31:AL31)
A32: Coûts variables
A33: Coût IA et outils (missions × coût par mission) | B33: € HT | C33: =(C19*Hypothèses!$C$31+C20*Hypothèses!$C$32+C21*Hypothèses!$C$33)*Hypothèses!$C$34*$F$4 | D33: =(D19*Hypothèses!$C$31+D20*Hypothèses!$C$32+D21*Hypothèses!$C$33)*Hypothèses!$C$34*$F$4 | E33: =(E19*Hypothèses!$C$31+E20*Hypothèses!$C$32+E21*Hypothèses!$C$33)*Hypothèses!$C$34*$F$4 | F33: =(F19*Hypothèses!$C$31+F20*Hypothèses!$C$32+F21*Hypothèses!$C$33)*Hypothèses!$C$34*$F$4 | G33: =(G19*Hypothèses!$C$31+G20*Hypothèses!$C$32+G21*Hypothèses!$C$33)*Hypothèses!$C$34*$F$4 | H33: =(H19*Hypothèses!$C$31+H20*Hypothèses!$C$32+H21*Hypothèses!$C$33)*Hypothèses!$C$34*$F$4 | I33: =(I19*Hypothèses!$C$31+I20*Hypothèses!$C$32+I21*Hypothèses!$C$33)*Hypothèses!$C$34*$F$4 | J33: =(J19*Hypothèses!$C$31+J20*Hypothèses!$C$32+J21*Hypothèses!$C$33)*Hypothèses!$C$34*$F$4 | ... AL33: =(AL19*Hypothèses!$C$31+AL20*Hypothèses!$C$32+AL21*Hypothèses!$C$33)*Hypothèses!$C$34*$F$4 | AN33: =SUM(C33:N33) | AO33: =SUM(O33:Z33) | AP33: =SUM(AA33:AL33)
A34: Hébergement, stockage, connecteurs | B34: € HT | C34: =C18*Hypothèses!$C$35 | D34: =D18*Hypothèses!$C$35 | E34: =E18*Hypothèses!$C$35 | F34: =F18*Hypothèses!$C$35 | G34: =G18*Hypothèses!$C$35 | H34: =H18*Hypothèses!$C$35 | I34: =I18*Hypothèses!$C$35 | J34: =J18*Hypothèses!$C$35 | ... AL34: =AL18*Hypothèses!$C$35 | AN34: =SUM(C34:N34) | AO34: =SUM(O34:Z34) | AP34: =SUM(AA34:AL34)
A35: Support humain | B35: € HT | C35: =C18*Hypothèses!$C$36 | D35: =D18*Hypothèses!$C$36 | E35: =E18*Hypothèses!$C$36 | F35: =F18*Hypothèses!$C$36 | G35: =G18*Hypothèses!$C$36 | H35: =H18*Hypothèses!$C$36 | I35: =I18*Hypothèses!$C$36 | J35: =J18*Hypothèses!$C$36 | ... AL35: =AL18*Hypothèses!$C$36 | AN35: =SUM(C35:N35) | AO35: =SUM(O35:Z35) | AP35: =SUM(AA35:AL35)
A36: Total coûts variables | B36: € HT | C36: =C33+C34+C35 | D36: =D33+D34+D35 | E36: =E33+E34+E35 | F36: =F33+F34+F35 | G36: =G33+G34+G35 | H36: =H33+H34+H35 | I36: =I33+I34+I35 | J36: =J33+J34+J35 | ... AL36: =AL33+AL34+AL35 | AN36: =SUM(C36:N36) | AO36: =SUM(O36:Z36) | AP36: =SUM(AA36:AL36)
A37: Marge sur coûts variables (CA HT − variables − frais − impayés HT) | B37: € HT | C37: =C28-C36-C30-C29/(1+Hypothèses!$C$15) | D37: =D28-D36-D30-D29/(1+Hypothèses!$C$15) | E37: =E28-E36-E30-E29/(1+Hypothèses!$C$15) | F37: =F28-F36-F30-F29/(1+Hypothèses!$C$15) | G37: =G28-G36-G30-G29/(1+Hypothèses!$C$15) | H37: =H28-H36-H30-H29/(1+Hypothèses!$C$15) | I37: =I28-I36-I30-I29/(1+Hypothèses!$C$15) | J37: =J28-J36-J30-J29/(1+Hypothèses!$C$15) | ... AL37: =AL28-AL36-AL30-AL29/(1+Hypothèses!$C$15) | AN37: =SUM(C37:N37) | AO37: =SUM(O37:Z37) | AP37: =SUM(AA37:AL37)
A38: Acquisition et coûts fixes
A39: Dépenses d'acquisition | B39: € HT | C39: =C11 | D39: =D11 | E39: =E11 | F39: =F11 | G39: =G11 | H39: =H11 | I39: =I11 | J39: =J11 | ... AL39: =AL11 | AN39: =SUM(C39:N39) | AO39: =SUM(O39:Z39) | AP39: =SUM(AA39:AL39)
A40: Rémunération des fondateurs | B40: € HT | C40: =IF(C7>=Hypothèses!$C$39,Hypothèses!$C$38*Hypothèses!$C$40,0)*$G$4 | D40: =IF(D7>=Hypothèses!$C$39,Hypothèses!$C$38*Hypothèses!$C$40,0)*$G$4 | E40: =IF(E7>=Hypothèses!$C$39,Hypothèses!$C$38*Hypothèses!$C$40,0)*$G$4 | F40: =IF(F7>=Hypothèses!$C$39,Hypothèses!$C$38*Hypothèses!$C$40,0)*$G$4 | G40: =IF(G7>=Hypothèses!$C$39,Hypothèses!$C$38*Hypothèses!$C$40,0)*$G$4 | H40: =IF(H7>=Hypothèses!$C$39,Hypothèses!$C$38*Hypothèses!$C$40,0)*$G$4 | I40: =IF(I7>=Hypothèses!$C$39,Hypothèses!$C$38*Hypothèses!$C$40,0)*$G$4 | J40: =IF(J7>=Hypothèses!$C$39,Hypothèses!$C$38*Hypothèses!$C$40,0)*$G$4 | ... AL40: =IF(AL7>=Hypothèses!$C$39,Hypothèses!$C$38*Hypothèses!$C$40,0)*$G$4 | AN40: =SUM(C40:N40) | AO40: =SUM(O40:Z40) | AP40: =SUM(AA40:AL40)
...

Sheet Modèle Central
A1: Modèle Central (36 mois)
A2: Flux en € HT sauf mention TTC. Formules vivantes ; ne saisir que dans l'onglet Hypothèses et la ligne de chocs ci-dessous.
A3: Chocs de sensibilité (1 = aucun ; retard en mois) | C3: Prix × | D3: Churn × | E3: CAC × | F3: Coût IA × | G3: Coûts fixes × | H3: Retard lancement (mois)
C4: 1 | D4: 1 | E4: 1 | F4: 1 | G4: 1 | H4: 0
A5: Mois de lancement effectif | B5: =Hypothèses!$D$10+$H$4
A6: Ligne | B6: Unité | C6: M1 | D6: M2 | E6: M3 | F6: M4 | G6: M5 | H6: M6 | I6: M7 | J6: M8 | K6: M9 | L6: M10 | M6: M11 | N6: M12 | O6: M13 | P6: M14 | Q6: M15 | R6: M16 | S6: M17 | T6: M18 | U6: M19 | V6: M20 | W6: M21 | X6: M22 | Y6: M23 | Z6: M24 | AA6: M25 | AB6: M26 | AC6: M27 | AD6: M28 | AE6: M29 | AF6: M30 | AG6: M31 | AH6: M32 | AI6: M33 | AJ6: M34 | AK6: M35 | AL6: M36 | AN6: Année 1 | AO6: Année 2 | AP6: Année 3
A7: Mois | B7: n° | C7: 1 | D7: 2 | E7: 3 | F7: 4 | G7: 5 | H7: 6 | I7: 7 | J7: 8 | K7: 9 | L7: 10 | M7: 11 | N7: 12 | O7: 13 | P7: 14 | Q7: 15 | R7: 16 | S7: 17 | T7: 18 | U7: 19 | V7: 20 | W7: 21 | X7: 22 | Y7: 23 | Z7: 24 | AA7: 25 | AB7: 26 | AC7: 27 | AD7: 28 | AE7: 29 | AF7: 30 | AG7: 31 | AH7: 32 | AI7: 33 | AJ7: 34 | AK7: 35 | AL7: 36
A8: Date | C8: =EDATE(Hypothèses!$D$7,C7-1) | D8: =EDATE(Hypothèses!$D$7,D7-1) | E8: =EDATE(Hypothèses!$D$7,E7-1) | F8: =EDATE(Hypothèses!$D$7,F7-1) | G8: =EDATE(Hypothèses!$D$7,G7-1) | H8: =EDATE(Hypothèses!$D$7,H7-1) | I8: =EDATE(Hypothèses!$D$7,I7-1) | J8: =EDATE(Hypothèses!$D$7,J7-1) | ... AL8: =EDATE(Hypothèses!$D$7,AL7-1)
A9: Lancé ? (1 = oui) | B9: 0/1 | C9: =IF(C7>=$B$5,1,0) | D9: =IF(D7>=$B$5,1,0) | E9: =IF(E7>=$B$5,1,0) | F9: =IF(F7>=$B$5,1,0) | G9: =IF(G7>=$B$5,1,0) | H9: =IF(H7>=$B$5,1,0) | I9: =IF(I7>=$B$5,1,0) | J9: =IF(J7>=$B$5,1,0) | ... AL9: =IF(AL7>=$B$5,1,0)
A10: Pilote en cours ? (1 = oui) | B10: 0/1 | C10: =IF(AND(C7>=Hypothèses!$D$8,C7<$B$5),1,0) | D10: =IF(AND(D7>=Hypothèses!$D$8,D7<$B$5),1,0) | E10: =IF(AND(E7>=Hypothèses!$D$8,E7<$B$5),1,0) | F10: =IF(AND(F7>=Hypothèses!$D$8,F7<$B$5),1,0) | G10: =IF(AND(G7>=Hypothèses!$D$8,G7<$B$5),1,0) | H10: =IF(AND(H7>=Hypothèses!$D$8,H7<$B$5),1,0) | I10: =IF(AND(I7>=Hypothèses!$D$8,I7<$B$5),1,0) | J10: =IF(AND(J7>=Hypothèses!$D$8,J7<$B$5),1,0) | ... AL10: =IF(AND(AL7>=Hypothèses!$D$8,AL7<$B$5),1,0)
A11: Budget d'acquisition du mois | B11: € HT | C11: =IF(C9=1,IF(C7<=12,Hypothèses!$D$20,IF(C7<=24,Hypothèses!$D$21,Hypothèses!$D$22)),0) | D11: =IF(D9=1,IF(D7<=12,Hypothèses!$D$20,IF(D7<=24,Hypothèses!$D$21,Hypothèses!$D$22)),0) | E11: =IF(E9=1,IF(E7<=12,Hypothèses!$D$20,IF(E7<=24,Hypothèses!$D$21,Hypothèses!$D$22)),0) | F11: =IF(F9=1,IF(F7<=12,Hypothèses!$D$20,IF(F7<=24,Hypothèses!$D$21,Hypothèses!$D$22)),0) | G11: =IF(G9=1,IF(G7<=12,Hypothèses!$D$20,IF(G7<=24,Hypothèses!$D$21,Hypothèses!$D$22)),0) | H11: =IF(H9=1,IF(H7<=12,Hypothèses!$D$20,IF(H7<=24,Hypothèses!$D$21,Hypothèses!$D$22)),0) | I11: =IF(I9=1,IF(I7<=12,Hypothèses!$D$20,IF(I7<=24,Hypothèses!$D$21,Hypothèses!$D$22)),0) | J11: =IF(J9=1,IF(J7<=12,Hypothèses!$D$20,IF(J7<=24,Hypothèses!$D$21,Hypothèses!$D$22)),0) | ... AL11: =IF(AL9=1,IF(AL7<=12,Hypothèses!$D$20,IF(AL7<=24,Hypothèses!$D$21,Hypothèses!$D$22)),0) | AN11: =SUM(C11:N11) | AO11: =SUM(O11:Z11) | AP11: =SUM(AA11:AL11)
A12: Abonnés
A13: Abonnés en début de mois | B13: abonnés | C13: =0 | D13: =C18 | E13: =D18 | F13: =E18 | G13: =F18 | H13: =G18 | I13: =H18 | J13: =I18 | K13: =J18 | ... AL13: =AK18
A14: Nouveaux abonnés par acquisition payante | B14: abonnés | C14: =C11/(Hypothèses!$D$23*$E$4) | D14: =D11/(Hypothèses!$D$23*$E$4) | E14: =E11/(Hypothèses!$D$23*$E$4) | F14: =F11/(Hypothèses!$D$23*$E$4) | G14: =G11/(Hypothèses!$D$23*$E$4) | H14: =H11/(Hypothèses!$D$23*$E$4) | I14: =I11/(Hypothèses!$D$23*$E$4) | J14: =J11/(Hypothèses!$D$23*$E$4) | ... AL14: =AL11/(Hypothèses!$D$23*$E$4) | AN14: =SUM(C14:N14) | AO14: =SUM(O14:Z14) | AP14: =SUM(AA14:AL14)
A15: Nouveaux abonnés pilote | B15: abonnés | C15: =IF(C7=Hypothèses!$D$8,Hypothèses!$D$9,0) | D15: =IF(D7=Hypothèses!$D$8,Hypothèses!$D$9,0) | E15: =IF(E7=Hypothèses!$D$8,Hypothèses!$D$9,0) | F15: =IF(F7=Hypothèses!$D$8,Hypothèses!$D$9,0) | G15: =IF(G7=Hypothèses!$D$8,Hypothèses!$D$9,0) | H15: =IF(H7=Hypothèses!$D$8,Hypothèses!$D$9,0) | I15: =IF(I7=Hypothèses!$D$8,Hypothèses!$D$9,0) | J15: =IF(J7=Hypothèses!$D$8,Hypothèses!$D$9,0) | ... AL15: =IF(AL7=Hypothèses!$D$8,Hypothèses!$D$9,0) | AN15: =SUM(C15:N15) | AO15: =SUM(O15:Z15) | AP15: =SUM(AA15:AL15)
A16: Nouveaux abonnés organiques (parrainage) | B16: abonnés | C16: =C9*C13*Hypothèses!$D$24 | D16: =D9*D13*Hypothèses!$D$24 | E16: =E9*E13*Hypothèses!$D$24 | F16: =F9*F13*Hypothèses!$D$24 | G16: =G9*G13*Hypothèses!$D$24 | H16: =H9*H13*Hypothèses!$D$24 | I16: =I9*I13*Hypothèses!$D$24 | J16: =J9*J13*Hypothèses!$D$24 | ... AL16: =AL9*AL13*Hypothèses!$D$24 | AN16: =SUM(C16:N16) | AO16: =SUM(O16:Z16) | AP16: =SUM(AA16:AL16)
A17: Résiliations | B17: abonnés | C17: =C13*Hypothèses!$D$26*$D$4 | D17: =D13*Hypothèses!$D$26*$D$4 | E17: =E13*Hypothèses!$D$26*$D$4 | F17: =F13*Hypothèses!$D$26*$D$4 | G17: =G13*Hypothèses!$D$26*$D$4 | H17: =H13*Hypothèses!$D$26*$D$4 | I17: =I13*Hypothèses!$D$26*$D$4 | J17: =J13*Hypothèses!$D$26*$D$4 | ... AL17: =AL13*Hypothèses!$D$26*$D$4 | AN17: =SUM(C17:N17) | AO17: =SUM(O17:Z17) | AP17: =SUM(AA17:AL17)
A18: Abonnés en fin de mois | B18: abonnés | C18: =C13+C14+C15+C16-C17 | D18: =D13+D14+D15+D16-D17 | E18: =E13+E14+E15+E16-E17 | F18: =F13+F14+F15+F16-F17 | G18: =G13+G14+G15+G16-G17 | H18: =H13+H14+H15+H16-H17 | I18: =I13+I14+I15+I16-I17 | J18: =J13+J14+J15+J16-J17 | ... AL18: =AL13+AL14+AL15+AL16-AL17 | AN18: =N18 | AO18: =Z18 | AP18: =AL18
A19: dont Personal | B19: abonnés | C19: =C18*Hypothèses!$D$16 | D19: =D18*Hypothèses!$D$16 | E19: =E18*Hypothèses!$D$16 | F19: =F18*Hypothèses!$D$16 | G19: =G18*Hypothèses!$D$16 | H19: =H18*Hypothèses!$D$16 | I19: =I18*Hypothèses!$D$16 | J19: =J18*Hypothèses!$D$16 | ... AL19: =AL18*Hypothèses!$D$16 | AN19: =N19 | AO19: =Z19 | AP19: =AL19
A20: dont Premium | B20: abonnés | C20: =C18*Hypothèses!$D$17 | D20: =D18*Hypothèses!$D$17 | E20: =E18*Hypothèses!$D$17 | F20: =F18*Hypothèses!$D$17 | G20: =G18*Hypothèses!$D$17 | H20: =H18*Hypothèses!$D$17 | I20: =I18*Hypothèses!$D$17 | J20: =J18*Hypothèses!$D$17 | ... AL20: =AL18*Hypothèses!$D$17 | AN20: =N20 | AO20: =Z20 | AP20: =AL20
A21: dont Family | B21: abonnés | C21: =C18*Hypothèses!$D$18 | D21: =D18*Hypothèses!$D$18 | E21: =E18*Hypothèses!$D$18 | F21: =F18*Hypothèses!$D$18 | G21: =G18*Hypothèses!$D$18 | H21: =H18*Hypothèses!$D$18 | I21: =I18*Hypothèses!$D$18 | J21: =J18*Hypothèses!$D$18 | ... AL21: =AL18*Hypothèses!$D$18 | AN21: =N21 | AO21: =Z21 | AP21: =AL21
A22: Revenus
A23: Facturation Personal TTC | B23: € TTC | C23: =C19*Hypothèses!$D$12*$C$4 | D23: =D19*Hypothèses!$D$12*$C$4 | E23: =E19*Hypothèses!$D$12*$C$4 | F23: =F19*Hypothèses!$D$12*$C$4 | G23: =G19*Hypothèses!$D$12*$C$4 | H23: =H19*Hypothèses!$D$12*$C$4 | I23: =I19*Hypothèses!$D$12*$C$4 | J23: =J19*Hypothèses!$D$12*$C$4 | ... AL23: =AL19*Hypothèses!$D$12*$C$4 | AN23: =SUM(C23:N23) | AO23: =SUM(O23:Z23) | AP23: =SUM(AA23:AL23)
A24: Facturation Premium TTC | B24: € TTC | C24: =C20*Hypothèses!$D$13*$C$4 | D24: =D20*Hypothèses!$D$13*$C$4 | E24: =E20*Hypothèses!$D$13*$C$4 | F24: =F20*Hypothèses!$D$13*$C$4 | G24: =G20*Hypothèses!$D$13*$C$4 | H24: =H20*Hypothèses!$D$13*$C$4 | I24: =I20*Hypothèses!$D$13*$C$4 | J24: =J20*Hypothèses!$D$13*$C$4 | ... AL24: =AL20*Hypothèses!$D$13*$C$4 | AN24: =SUM(C24:N24) | AO24: =SUM(O24:Z24) | AP24: =SUM(AA24:AL24)
A25: Facturation Family TTC | B25: € TTC | C25: =C21*Hypothèses!$D$14*$C$4 | D25: =D21*Hypothèses!$D$14*$C$4 | E25: =E21*Hypothèses!$D$14*$C$4 | F25: =F21*Hypothèses!$D$14*$C$4 | G25: =G21*Hypothèses!$D$14*$C$4 | H25: =H21*Hypothèses!$D$14*$C$4 | I25: =I21*Hypothèses!$D$14*$C$4 | J25: =J21*Hypothèses!$D$14*$C$4 | ... AL25: =AL21*Hypothèses!$D$14*$C$4 | AN25: =SUM(C25:N25) | AO25: =SUM(O25:Z25) | AP25: =SUM(AA25:AL25)
A26: Facturation totale TTC (MRR TTC) | B26: € TTC | C26: =C23+C24+C25 | D26: =D23+D24+D25 | E26: =E23+E24+E25 | F26: =F23+F24+F25 | G26: =G23+G24+G25 | H26: =H23+H24+H25 | I26: =I23+I24+I25 | J26: =J23+J24+J25 | ... AL26: =AL23+AL24+AL25 | AN26: =SUM(C26:N26) | AO26: =SUM(O26:Z26) | AP26: =SUM(AA26:AL26)
A27: TVA collectée | B27: € | C27: =C26*Hypothèses!$D$15/(1+Hypothèses!$D$15) | D27: =D26*Hypothèses!$D$15/(1+Hypothèses!$D$15) | E27: =E26*Hypothèses!$D$15/(1+Hypothèses!$D$15) | F27: =F26*Hypothèses!$D$15/(1+Hypothèses!$D$15) | G27: =G26*Hypothèses!$D$15/(1+Hypothèses!$D$15) | H27: =H26*Hypothèses!$D$15/(1+Hypothèses!$D$15) | I27: =I26*Hypothèses!$D$15/(1+Hypothèses!$D$15) | J27: =J26*Hypothèses!$D$15/(1+Hypothèses!$D$15) | ... AL27: =AL26*Hypothèses!$D$15/(1+Hypothèses!$D$15) | AN27: =SUM(C27:N27) | AO27: =SUM(O27:Z27) | AP27: =SUM(AA27:AL27)
A28: Chiffre d'affaires HT | B28: € HT | C28: =C26-C27 | D28: =D26-D27 | E28: =E26-E27 | F28: =F26-F27 | G28: =G26-G27 | H28: =H26-H27 | I28: =I26-I27 | J28: =J26-J27 | ... AL28: =AL26-AL27 | AN28: =SUM(C28:N28) | AO28: =SUM(O28:Z28) | AP28: =SUM(AA28:AL28)
A29: Impayés (TTC) | B29: € TTC | C29: =C26*Hypothèses!$D$27 | D29: =D26*Hypothèses!$D$27 | E29: =E26*Hypothèses!$D$27 | F29: =F26*Hypothèses!$D$27 | G29: =G26*Hypothèses!$D$27 | H29: =H26*Hypothèses!$D$27 | I29: =I26*Hypothèses!$D$27 | J29: =J26*Hypothèses!$D$27 | ... AL29: =AL26*Hypothèses!$D$27 | AN29: =SUM(C29:N29) | AO29: =SUM(O29:Z29) | AP29: =SUM(AA29:AL29)
A30: Frais de paiement | B30: € | C30: =(C26-C29)*Hypothèses!$D$28+C18*Hypothèses!$D$29 | D30: =(D26-D29)*Hypothèses!$D$28+D18*Hypothèses!$D$29 | E30: =(E26-E29)*Hypothèses!$D$28+E18*Hypothèses!$D$29 | F30: =(F26-F29)*Hypothèses!$D$28+F18*Hypothèses!$D$29 | G30: =(G26-G29)*Hypothèses!$D$28+G18*Hypothèses!$D$29 | H30: =(H26-H29)*Hypothèses!$D$28+H18*Hypothèses!$D$29 | I30: =(I26-I29)*Hypothèses!$D$28+I18*Hypothèses!$D$29 | J30: =(J26-J29)*Hypothèses!$D$28+J18*Hypothèses!$D$29 | ... AL30: =(AL26-AL29)*Hypothèses!$D$28+AL18*Hypothèses!$D$29 | AN30: =SUM(C30:N30) | AO30: =SUM(O30:Z30) | AP30: =SUM(AA30:AL30)
A31: Encaissements nets TTC | B31: € TTC | C31: =C26-C29-C30 | D31: =D26-D29-D30 | E31: =E26-E29-E30 | F31: =F26-F29-F30 | G31: =G26-G29-G30 | H31: =H26-H29-H30 | I31: =I26-I29-I30 | J31: =J26-J29-J30 | ... AL31: =AL26-AL29-AL30 | AN31: =SUM(C31:N31) | AO31: =SUM(O31:Z31) | AP31: =SUM(AA31:AL31)
A32: Coûts variables
A33: Coût IA et outils (missions × coût par mission) | B33: € HT | C33: =(C19*Hypothèses!$D$31+C20*Hypothèses!$D$32+C21*Hypothèses!$D$33)*Hypothèses!$D$34*$F$4 | D33: =(D19*Hypothèses!$D$31+D20*Hypothèses!$D$32+D21*Hypothèses!$D$33)*Hypothèses!$D$34*$F$4 | E33: =(E19*Hypothèses!$D$31+E20*Hypothèses!$D$32+E21*Hypothèses!$D$33)*Hypothèses!$D$34*$F$4 | F33: =(F19*Hypothèses!$D$31+F20*Hypothèses!$D$32+F21*Hypothèses!$D$33)*Hypothèses!$D$34*$F$4 | G33: =(G19*Hypothèses!$D$31+G20*Hypothèses!$D$32+G21*Hypothèses!$D$33)*Hypothèses!$D$34*$F$4 | H33: =(H19*Hypothèses!$D$31+H20*Hypothèses!$D$32+H21*Hypothèses!$D$33)*Hypothèses!$D$34*$F$4 | I33: =(I19*Hypothèses!$D$31+I20*Hypothèses!$D$32+I21*Hypothèses!$D$33)*Hypothèses!$D$34*$F$4 | J33: =(J19*Hypothèses!$D$31+J20*Hypothèses!$D$32+J21*Hypothèses!$D$33)*Hypothèses!$D$34*$F$4 | ... AL33: =(AL19*Hypothèses!$D$31+AL20*Hypothèses!$D$32+AL21*Hypothèses!$D$33)*Hypothèses!$D$34*$F$4 | AN33: =SUM(C33:N33) | AO33: =SUM(O33:Z33) | AP33: =SUM(AA33:AL33)
A34: Hébergement, stockage, connecteurs | B34: € HT | C34: =C18*Hypothèses!$D$35 | D34: =D18*Hypothèses!$D$35 | E34: =E18*Hypothèses!$D$35 | F34: =F18*Hypothèses!$D$35 | G34: =G18*Hypothèses!$D$35 | H34: =H18*Hypothèses!$D$35 | I34: =I18*Hypothèses!$D$35 | J34: =J18*Hypothèses!$D$35 | ... AL34: =AL18*Hypothèses!$D$35 | AN34: =SUM(C34:N34) | AO34: =SUM(O34:Z34) | AP34: =SUM(AA34:AL34)
A35: Support humain | B35: € HT | C35: =C18*Hypothèses!$D$36 | D35: =D18*Hypothèses!$D$36 | E35: =E18*Hypothèses!$D$36 | F35: =F18*Hypothèses!$D$36 | G35: =G18*Hypothèses!$D$36 | H35: =H18*Hypothèses!$D$36 | I35: =I18*Hypothèses!$D$36 | J35: =J18*Hypothèses!$D$36 | ... AL35: =AL18*Hypothèses!$D$36 | AN35: =SUM(C35:N35) | AO35: =SUM(O35:Z35) | AP35: =SUM(AA35:AL35)
A36: Total coûts variables | B36: € HT | C36: =C33+C34+C35 | D36: =D33+D34+D35 | E36: =E33+E34+E35 | F36: =F33+F34+F35 | G36: =G33+G34+G35 | H36: =H33+H34+H35 | I36: =I33+I34+I35 | J36: =J33+J34+J35 | ... AL36: =AL33+AL34+AL35 | AN36: =SUM(C36:N36) | AO36: =SUM(O36:Z36) | AP36: =SUM(AA36:AL36)
A37: Marge sur coûts variables (CA HT − variables − frais − impayés HT) | B37: € HT | C37: =C28-C36-C30-C29/(1+Hypothèses!$D$15) | D37: =D28-D36-D30-D29/(1+Hypothèses!$D$15) | E37: =E28-E36-E30-E29/(1+Hypothèses!$D$15) | F37: =F28-F36-F30-F29/(1+Hypothèses!$D$15) | G37: =G28-G36-G30-G29/(1+Hypothèses!$D$15) | H37: =H28-H36-H30-H29/(1+Hypothèses!$D$15) | I37: =I28-I36-I30-I29/(1+Hypothèses!$D$15) | J37: =J28-J36-J30-J29/(1+Hypothèses!$D$15) | ... AL37: =AL28-AL36-AL30-AL29/(1+Hypothèses!$D$15) | AN37: =SUM(C37:N37) | AO37: =SUM(O37:Z37) | AP37: =SUM(AA37:AL37)
A38: Acquisition et coûts fixes
A39: Dépenses d'acquisition | B39: € HT | C39: =C11 | D39: =D11 | E39: =E11 | F39: =F11 | G39: =G11 | H39: =H11 | I39: =I11 | J39: =J11 | ... AL39: =AL11 | AN39: =SUM(C39:N39) | AO39: =SUM(O39:Z39) | AP39: =SUM(AA39:AL39)
A40: Rémunération des fondateurs | B40: € HT | C40: =IF(C7>=Hypothèses!$D$39,Hypothèses!$D$38*Hypothèses!$D$40,0)*$G$4 | D40: =IF(D7>=Hypothèses!$D$39,Hypothèses!$D$38*Hypothèses!$D$40,0)*$G$4 | E40: =IF(E7>=Hypothèses!$D$39,Hypothèses!$D$38*Hypothèses!$D$40,0)*$G$4 | F40: =IF(F7>=Hypothèses!$D$39,Hypothèses!$D$38*Hypothèses!$D$40,0)*$G$4 | G40: =IF(G7>=Hypothèses!$D$39,Hypothèses!$D$38*Hypothèses!$D$40,0)*$G$4 | H40: =IF(H7>=Hypothèses!$D$39,Hypothèses!$D$38*Hypothèses!$D$40,0)*$G$4 | I40: =IF(I7>=Hypothèses!$D$39,Hypothèses!$D$38*Hypothèses!$D$40,0)*$G$4 | J40: =IF(J7>=Hypothèses!$D$39,Hypothèses!$D$38*Hypothèses!$D$40,0)*$G$4 | ... AL40: =IF(AL7>=Hypothèses!$D$39,Hypothèses!$D$38*Hypothèses!$D$40,0)*$G$4 | AN40: =SUM(C40:N40) | AO40: =SUM(O40:Z40) | AP40: =SUM(AA40:AL40)
...

Sheet Modèle Ambitieux
A1: Modèle Ambitieux (36 mois)
A2: Flux en € HT sauf mention TTC. Formules vivantes ; ne saisir que dans l'onglet Hypothèses et la ligne de chocs ci-dessous.
A3: Chocs de sensibilité (1 = aucun ; retard en mois) | C3: Prix × | D3: Churn × | E3: CAC × | F3: Coût IA × | G3: Coûts fixes × | H3: Retard lancement (mois)
C4: 1 | D4: 1 | E4: 1 | F4: 1 | G4: 1 | H4: 0
A5: Mois de lancement effectif | B5: =Hypothèses!$E$10+$H$4
A6: Ligne | B6: Unité | C6: M1 | D6: M2 | E6: M3 | F6: M4 | G6: M5 | H6: M6 | I6: M7 | J6: M8 | K6: M9 | L6: M10 | M6: M11 | N6: M12 | O6: M13 | P6: M14 | Q6: M15 | R6: M16 | S6: M17 | T6: M18 | U6: M19 | V6: M20 | W6: M21 | X6: M22 | Y6: M23 | Z6: M24 | AA6: M25 | AB6: M26 | AC6: M27 | AD6: M28 | AE6: M29 | AF6: M30 | AG6: M31 | AH6: M32 | AI6: M33 | AJ6: M34 | AK6: M35 | AL6: M36 | AN6: Année 1 | AO6: Année 2 | AP6: Année 3
A7: Mois | B7: n° | C7: 1 | D7: 2 | E7: 3 | F7: 4 | G7: 5 | H7: 6 | I7: 7 | J7: 8 | K7: 9 | L7: 10 | M7: 11 | N7: 12 | O7: 13 | P7: 14 | Q7: 15 | R7: 16 | S7: 17 | T7: 18 | U7: 19 | V7: 20 | W7: 21 | X7: 22 | Y7: 23 | Z7: 24 | AA7: 25 | AB7: 26 | AC7: 27 | AD7: 28 | AE7: 29 | AF7: 30 | AG7: 31 | AH7: 32 | AI7: 33 | AJ7: 34 | AK7: 35 | AL7: 36
A8: Date | C8: =EDATE(Hypothèses!$E$7,C7-1) | D8: =EDATE(Hypothèses!$E$7,D7-1) | E8: =EDATE(Hypothèses!$E$7,E7-1) | F8: =EDATE(Hypothèses!$E$7,F7-1) | G8: =EDATE(Hypothèses!$E$7,G7-1) | H8: =EDATE(Hypothèses!$E$7,H7-1) | I8: =EDATE(Hypothèses!$E$7,I7-1) | J8: =EDATE(Hypothèses!$E$7,J7-1) | ... AL8: =EDATE(Hypothèses!$E$7,AL7-1)
A9: Lancé ? (1 = oui) | B9: 0/1 | C9: =IF(C7>=$B$5,1,0) | D9: =IF(D7>=$B$5,1,0) | E9: =IF(E7>=$B$5,1,0) | F9: =IF(F7>=$B$5,1,0) | G9: =IF(G7>=$B$5,1,0) | H9: =IF(H7>=$B$5,1,0) | I9: =IF(I7>=$B$5,1,0) | J9: =IF(J7>=$B$5,1,0) | ... AL9: =IF(AL7>=$B$5,1,0)
A10: Pilote en cours ? (1 = oui) | B10: 0/1 | C10: =IF(AND(C7>=Hypothèses!$E$8,C7<$B$5),1,0) | D10: =IF(AND(D7>=Hypothèses!$E$8,D7<$B$5),1,0) | E10: =IF(AND(E7>=Hypothèses!$E$8,E7<$B$5),1,0) | F10: =IF(AND(F7>=Hypothèses!$E$8,F7<$B$5),1,0) | G10: =IF(AND(G7>=Hypothèses!$E$8,G7<$B$5),1,0) | H10: =IF(AND(H7>=Hypothèses!$E$8,H7<$B$5),1,0) | I10: =IF(AND(I7>=Hypothèses!$E$8,I7<$B$5),1,0) | J10: =IF(AND(J7>=Hypothèses!$E$8,J7<$B$5),1,0) | ... AL10: =IF(AND(AL7>=Hypothèses!$E$8,AL7<$B$5),1,0)
A11: Budget d'acquisition du mois | B11: € HT | C11: =IF(C9=1,IF(C7<=12,Hypothèses!$E$20,IF(C7<=24,Hypothèses!$E$21,Hypothèses!$E$22)),0) | D11: =IF(D9=1,IF(D7<=12,Hypothèses!$E$20,IF(D7<=24,Hypothèses!$E$21,Hypothèses!$E$22)),0) | E11: =IF(E9=1,IF(E7<=12,Hypothèses!$E$20,IF(E7<=24,Hypothèses!$E$21,Hypothèses!$E$22)),0) | F11: =IF(F9=1,IF(F7<=12,Hypothèses!$E$20,IF(F7<=24,Hypothèses!$E$21,Hypothèses!$E$22)),0) | G11: =IF(G9=1,IF(G7<=12,Hypothèses!$E$20,IF(G7<=24,Hypothèses!$E$21,Hypothèses!$E$22)),0) | H11: =IF(H9=1,IF(H7<=12,Hypothèses!$E$20,IF(H7<=24,Hypothèses!$E$21,Hypothèses!$E$22)),0) | I11: =IF(I9=1,IF(I7<=12,Hypothèses!$E$20,IF(I7<=24,Hypothèses!$E$21,Hypothèses!$E$22)),0) | J11: =IF(J9=1,IF(J7<=12,Hypothèses!$E$20,IF(J7<=24,Hypothèses!$E$21,Hypothèses!$E$22)),0) | ... AL11: =IF(AL9=1,IF(AL7<=12,Hypothèses!$E$20,IF(AL7<=24,Hypothèses!$E$21,Hypothèses!$E$22)),0) | AN11: =SUM(C11:N11) | AO11: =SUM(O11:Z11) | AP11: =SUM(AA11:AL11)
A12: Abonnés
A13: Abonnés en début de mois | B13: abonnés | C13: =0 | D13: =C18 | E13: =D18 | F13: =E18 | G13: =F18 | H13: =G18 | I13: =H18 | J13: =I18 | K13: =J18 | ... AL13: =AK18
A14: Nouveaux abonnés par acquisition payante | B14: abonnés | C14: =C11/(Hypothèses!$E$23*$E$4) | D14: =D11/(Hypothèses!$E$23*$E$4) | E14: =E11/(Hypothèses!$E$23*$E$4) | F14: =F11/(Hypothèses!$E$23*$E$4) | G14: =G11/(Hypothèses!$E$23*$E$4) | H14: =H11/(Hypothèses!$E$23*$E$4) | I14: =I11/(Hypothèses!$E$23*$E$4) | J14: =J11/(Hypothèses!$E$23*$E$4) | ... AL14: =AL11/(Hypothèses!$E$23*$E$4) | AN14: =SUM(C14:N14) | AO14: =SUM(O14:Z14) | AP14: =SUM(AA14:AL14)
A15: Nouveaux abonnés pilote | B15: abonnés | C15: =IF(C7=Hypothèses!$E$8,Hypothèses!$E$9,0) | D15: =IF(D7=Hypothèses!$E$8,Hypothèses!$E$9,0) | E15: =IF(E7=Hypothèses!$E$8,Hypothèses!$E$9,0) | F15: =IF(F7=Hypothèses!$E$8,Hypothèses!$E$9,0) | G15: =IF(G7=Hypothèses!$E$8,Hypothèses!$E$9,0) | H15: =IF(H7=Hypothèses!$E$8,Hypothèses!$E$9,0) | I15: =IF(I7=Hypothèses!$E$8,Hypothèses!$E$9,0) | J15: =IF(J7=Hypothèses!$E$8,Hypothèses!$E$9,0) | ... AL15: =IF(AL7=Hypothèses!$E$8,Hypothèses!$E$9,0) | AN15: =SUM(C15:N15) | AO15: =SUM(O15:Z15) | AP15: =SUM(AA15:AL15)
A16: Nouveaux abonnés organiques (parrainage) | B16: abonnés | C16: =C9*C13*Hypothèses!$E$24 | D16: =D9*D13*Hypothèses!$E$24 | E16: =E9*E13*Hypothèses!$E$24 | F16: =F9*F13*Hypothèses!$E$24 | G16: =G9*G13*Hypothèses!$E$24 | H16: =H9*H13*Hypothèses!$E$24 | I16: =I9*I13*Hypothèses!$E$24 | J16: =J9*J13*Hypothèses!$E$24 | ... AL16: =AL9*AL13*Hypothèses!$E$24 | AN16: =SUM(C16:N16) | AO16: =SUM(O16:Z16) | AP16: =SUM(AA16:AL16)
A17: Résiliations | B17: abonnés | C17: =C13*Hypothèses!$E$26*$D$4 | D17: =D13*Hypothèses!$E$26*$D$4 | E17: =E13*Hypothèses!$E$26*$D$4 | F17: =F13*Hypothèses!$E$26*$D$4 | G17: =G13*Hypothèses!$E$26*$D$4 | H17: =H13*Hypothèses!$E$26*$D$4 | I17: =I13*Hypothèses!$E$26*$D$4 | J17: =J13*Hypothèses!$E$26*$D$4 | ... AL17: =AL13*Hypothèses!$E$26*$D$4 | AN17: =SUM(C17:N17) | AO17: =SUM(O17:Z17) | AP17: =SUM(AA17:AL17)
A18: Abonnés en fin de mois | B18: abonnés | C18: =C13+C14+C15+C16-C17 | D18: =D13+D14+D15+D16-D17 | E18: =E13+E14+E15+E16-E17 | F18: =F13+F14+F15+F16-F17 | G18: =G13+G14+G15+G16-G17 | H18: =H13+H14+H15+H16-H17 | I18: =I13+I14+I15+I16-I17 | J18: =J13+J14+J15+J16-J17 | ... AL18: =AL13+AL14+AL15+AL16-AL17 | AN18: =N18 | AO18: =Z18 | AP18: =AL18
A19: dont Personal | B19: abonnés | C19: =C18*Hypothèses!$E$16 | D19: =D18*Hypothèses!$E$16 | E19: =E18*Hypothèses!$E$16 | F19: =F18*Hypothèses!$E$16 | G19: =G18*Hypothèses!$E$16 | H19: =H18*Hypothèses!$E$16 | I19: =I18*Hypothèses!$E$16 | J19: =J18*Hypothèses!$E$16 | ... AL19: =AL18*Hypothèses!$E$16 | AN19: =N19 | AO19: =Z19 | AP19: =AL19
A20: dont Premium | B20: abonnés | C20: =C18*Hypothèses!$E$17 | D20: =D18*Hypothèses!$E$17 | E20: =E18*Hypothèses!$E$17 | F20: =F18*Hypothèses!$E$17 | G20: =G18*Hypothèses!$E$17 | H20: =H18*Hypothèses!$E$17 | I20: =I18*Hypothèses!$E$17 | J20: =J18*Hypothèses!$E$17 | ... AL20: =AL18*Hypothèses!$E$17 | AN20: =N20 | AO20: =Z20 | AP20: =AL20
A21: dont Family | B21: abonnés | C21: =C18*Hypothèses!$E$18 | D21: =D18*Hypothèses!$E$18 | E21: =E18*Hypothèses!$E$18 | F21: =F18*Hypothèses!$E$18 | G21: =G18*Hypothèses!$E$18 | H21: =H18*Hypothèses!$E$18 | I21: =I18*Hypothèses!$E$18 | J21: =J18*Hypothèses!$E$18 | ... AL21: =AL18*Hypothèses!$E$18 | AN21: =N21 | AO21: =Z21 | AP21: =AL21
A22: Revenus
A23: Facturation Personal TTC | B23: € TTC | C23: =C19*Hypothèses!$E$12*$C$4 | D23: =D19*Hypothèses!$E$12*$C$4 | E23: =E19*Hypothèses!$E$12*$C$4 | F23: =F19*Hypothèses!$E$12*$C$4 | G23: =G19*Hypothèses!$E$12*$C$4 | H23: =H19*Hypothèses!$E$12*$C$4 | I23: =I19*Hypothèses!$E$12*$C$4 | J23: =J19*Hypothèses!$E$12*$C$4 | ... AL23: =AL19*Hypothèses!$E$12*$C$4 | AN23: =SUM(C23:N23) | AO23: =SUM(O23:Z23) | AP23: =SUM(AA23:AL23)
A24: Facturation Premium TTC | B24: € TTC | C24: =C20*Hypothèses!$E$13*$C$4 | D24: =D20*Hypothèses!$E$13*$C$4 | E24: =E20*Hypothèses!$E$13*$C$4 | F24: =F20*Hypothèses!$E$13*$C$4 | G24: =G20*Hypothèses!$E$13*$C$4 | H24: =H20*Hypothèses!$E$13*$C$4 | I24: =I20*Hypothèses!$E$13*$C$4 | J24: =J20*Hypothèses!$E$13*$C$4 | ... AL24: =AL20*Hypothèses!$E$13*$C$4 | AN24: =SUM(C24:N24) | AO24: =SUM(O24:Z24) | AP24: =SUM(AA24:AL24)
A25: Facturation Family TTC | B25: € TTC | C25: =C21*Hypothèses!$E$14*$C$4 | D25: =D21*Hypothèses!$E$14*$C$4 | E25: =E21*Hypothèses!$E$14*$C$4 | F25: =F21*Hypothèses!$E$14*$C$4 | G25: =G21*Hypothèses!$E$14*$C$4 | H25: =H21*Hypothèses!$E$14*$C$4 | I25: =I21*Hypothèses!$E$14*$C$4 | J25: =J21*Hypothèses!$E$14*$C$4 | ... AL25: =AL21*Hypothèses!$E$14*$C$4 | AN25: =SUM(C25:N25) | AO25: =SUM(O25:Z25) | AP25: =SUM(AA25:AL25)
A26: Facturation totale TTC (MRR TTC) | B26: € TTC | C26: =C23+C24+C25 | D26: =D23+D24+D25 | E26: =E23+E24+E25 | F26: =F23+F24+F25 | G26: =G23+G24+G25 | H26: =H23+H24+H25 | I26: =I23+I24+I25 | J26: =J23+J24+J25 | ... AL26: =AL23+AL24+AL25 | AN26: =SUM(C26:N26) | AO26: =SUM(O26:Z26) | AP26: =SUM(AA26:AL26)
A27: TVA collectée | B27: € | C27: =C26*Hypothèses!$E$15/(1+Hypothèses!$E$15) | D27: =D26*Hypothèses!$E$15/(1+Hypothèses!$E$15) | E27: =E26*Hypothèses!$E$15/(1+Hypothèses!$E$15) | F27: =F26*Hypothèses!$E$15/(1+Hypothèses!$E$15) | G27: =G26*Hypothèses!$E$15/(1+Hypothèses!$E$15) | H27: =H26*Hypothèses!$E$15/(1+Hypothèses!$E$15) | I27: =I26*Hypothèses!$E$15/(1+Hypothèses!$E$15) | J27: =J26*Hypothèses!$E$15/(1+Hypothèses!$E$15) | ... AL27: =AL26*Hypothèses!$E$15/(1+Hypothèses!$E$15) | AN27: =SUM(C27:N27) | AO27: =SUM(O27:Z27) | AP27: =SUM(AA27:AL27)
A28: Chiffre d'affaires HT | B28: € HT | C28: =C26-C27 | D28: =D26-D27 | E28: =E26-E27 | F28: =F26-F27 | G28: =G26-G27 | H28: =H26-H27 | I28: =I26-I27 | J28: =J26-J27 | ... AL28: =AL26-AL27 | AN28: =SUM(C28:N28) | AO28: =SUM(O28:Z28) | AP28: =SUM(AA28:AL28)
A29: Impayés (TTC) | B29: € TTC | C29: =C26*Hypothèses!$E$27 | D29: =D26*Hypothèses!$E$27 | E29: =E26*Hypothèses!$E$27 | F29: =F26*Hypothèses!$E$27 | G29: =G26*Hypothèses!$E$27 | H29: =H26*Hypothèses!$E$27 | I29: =I26*Hypothèses!$E$27 | J29: =J26*Hypothèses!$E$27 | ... AL29: =AL26*Hypothèses!$E$27 | AN29: =SUM(C29:N29) | AO29: =SUM(O29:Z29) | AP29: =SUM(AA29:AL29)
A30: Frais de paiement | B30: € | C30: =(C26-C29)*Hypothèses!$E$28+C18*Hypothèses!$E$29 | D30: =(D26-D29)*Hypothèses!$E$28+D18*Hypothèses!$E$29 | E30: =(E26-E29)*Hypothèses!$E$28+E18*Hypothèses!$E$29 | F30: =(F26-F29)*Hypothèses!$E$28+F18*Hypothèses!$E$29 | G30: =(G26-G29)*Hypothèses!$E$28+G18*Hypothèses!$E$29 | H30: =(H26-H29)*Hypothèses!$E$28+H18*Hypothèses!$E$29 | I30: =(I26-I29)*Hypothèses!$E$28+I18*Hypothèses!$E$29 | J30: =(J26-J29)*Hypothèses!$E$28+J18*Hypothèses!$E$29 | ... AL30: =(AL26-AL29)*Hypothèses!$E$28+AL18*Hypothèses!$E$29 | AN30: =SUM(C30:N30) | AO30: =SUM(O30:Z30) | AP30: =SUM(AA30:AL30)
A31: Encaissements nets TTC | B31: € TTC | C31: =C26-C29-C30 | D31: =D26-D29-D30 | E31: =E26-E29-E30 | F31: =F26-F29-F30 | G31: =G26-G29-G30 | H31: =H26-H29-H30 | I31: =I26-I29-I30 | J31: =J26-J29-J30 | ... AL31: =AL26-AL29-AL30 | AN31: =SUM(C31:N31) | AO31: =SUM(O31:Z31) | AP31: =SUM(AA31:AL31)
A32: Coûts variables
A33: Coût IA et outils (missions × coût par mission) | B33: € HT | C33: =(C19*Hypothèses!$E$31+C20*Hypothèses!$E$32+C21*Hypothèses!$E$33)*Hypothèses!$E$34*$F$4 | D33: =(D19*Hypothèses!$E$31+D20*Hypothèses!$E$32+D21*Hypothèses!$E$33)*Hypothèses!$E$34*$F$4 | E33: =(E19*Hypothèses!$E$31+E20*Hypothèses!$E$32+E21*Hypothèses!$E$33)*Hypothèses!$E$34*$F$4 | F33: =(F19*Hypothèses!$E$31+F20*Hypothèses!$E$32+F21*Hypothèses!$E$33)*Hypothèses!$E$34*$F$4 | G33: =(G19*Hypothèses!$E$31+G20*Hypothèses!$E$32+G21*Hypothèses!$E$33)*Hypothèses!$E$34*$F$4 | H33: =(H19*Hypothèses!$E$31+H20*Hypothèses!$E$32+H21*Hypothèses!$E$33)*Hypothèses!$E$34*$F$4 | I33: =(I19*Hypothèses!$E$31+I20*Hypothèses!$E$32+I21*Hypothèses!$E$33)*Hypothèses!$E$34*$F$4 | J33: =(J19*Hypothèses!$E$31+J20*Hypothèses!$E$32+J21*Hypothèses!$E$33)*Hypothèses!$E$34*$F$4 | ... AL33: =(AL19*Hypothèses!$E$31+AL20*Hypothèses!$E$32+AL21*Hypothèses!$E$33)*Hypothèses!$E$34*$F$4 | AN33: =SUM(C33:N33) | AO33: =SUM(O33:Z33) | AP33: =SUM(AA33:AL33)
A34: Hébergement, stockage, connecteurs | B34: € HT | C34: =C18*Hypothèses!$E$35 | D34: =D18*Hypothèses!$E$35 | E34: =E18*Hypothèses!$E$35 | F34: =F18*Hypothèses!$E$35 | G34: =G18*Hypothèses!$E$35 | H34: =H18*Hypothèses!$E$35 | I34: =I18*Hypothèses!$E$35 | J34: =J18*Hypothèses!$E$35 | ... AL34: =AL18*Hypothèses!$E$35 | AN34: =SUM(C34:N34) | AO34: =SUM(O34:Z34) | AP34: =SUM(AA34:AL34)
A35: Support humain | B35: € HT | C35: =C18*Hypothèses!$E$36 | D35: =D18*Hypothèses!$E$36 | E35: =E18*Hypothèses!$E$36 | F35: =F18*Hypothèses!$E$36 | G35: =G18*Hypothèses!$E$36 | H35: =H18*Hypothèses!$E$36 | I35: =I18*Hypothèses!$E$36 | J35: =J18*Hypothèses!$E$36 | ... AL35: =AL18*Hypothèses!$E$36 | AN35: =SUM(C35:N35) | AO35: =SUM(O35:Z35) | AP35: =SUM(AA35:AL35)
A36: Total coûts variables | B36: € HT | C36: =C33+C34+C35 | D36: =D33+D34+D35 | E36: =E33+E34+E35 | F36: =F33+F34+F35 | G36: =G33+G34+G35 | H36: =H33+H34+H35 | I36: =I33+I34+I35 | J36: =J33+J34+J35 | ... AL36: =AL33+AL34+AL35 | AN36: =SUM(C36:N36) | AO36: =SUM(O36:Z36) | AP36: =SUM(AA36:AL36)
A37: Marge sur coûts variables (CA HT − variables − frais − impayés HT) | B37: € HT | C37: =C28-C36-C30-C29/(1+Hypothèses!$E$15) | D37: =D28-D36-D30-D29/(1+Hypothèses!$E$15) | E37: =E28-E36-E30-E29/(1+Hypothèses!$E$15) | F37: =F28-F36-F30-F29/(1+Hypothèses!$E$15) | G37: =G28-G36-G30-G29/(1+Hypothèses!$E$15) | H37: =H28-H36-H30-H29/(1+Hypothèses!$E$15) | I37: =I28-I36-I30-I29/(1+Hypothèses!$E$15) | J37: =J28-J36-J30-J29/(1+Hypothèses!$E$15) | ... AL37: =AL28-AL36-AL30-AL29/(1+Hypothèses!$E$15) | AN37: =SUM(C37:N37) | AO37: =SUM(O37:Z37) | AP37: =SUM(AA37:AL37)
A38: Acquisition et coûts fixes
A39: Dépenses d'acquisition | B39: € HT | C39: =C11 | D39: =D11 | E39: =E11 | F39: =F11 | G39: =G11 | H39: =H11 | I39: =I11 | J39: =J11 | ... AL39: =AL11 | AN39: =SUM(C39:N39) | AO39: =SUM(O39:Z39) | AP39: =SUM(AA39:AL39)
A40: Rémunération des fondateurs | B40: € HT | C40: =IF(C7>=Hypothèses!$E$39,Hypothèses!$E$38*Hypothèses!$E$40,0)*$G$4 | D40: =IF(D7>=Hypothèses!$E$39,Hypothèses!$E$38*Hypothèses!$E$40,0)*$G$4 | E40: =IF(E7>=Hypothèses!$E$39,Hypothèses!$E$38*Hypothèses!$E$40,0)*$G$4 | F40: =IF(F7>=Hypothèses!$E$39,Hypothèses!$E$38*Hypothèses!$E$40,0)*$G$4 | G40: =IF(G7>=Hypothèses!$E$39,Hypothèses!$E$38*Hypothèses!$E$40,0)*$G$4 | H40: =IF(H7>=Hypothèses!$E$39,Hypothèses!$E$38*Hypothèses!$E$40,0)*$G$4 | I40: =IF(I7>=Hypothèses!$E$39,Hypothèses!$E$38*Hypothèses!$E$40,0)*$G$4 | J40: =IF(J7>=Hypothèses!$E$39,Hypothèses!$E$38*Hypothèses!$E$40,0)*$G$4 | ... AL40: =IF(AL7>=Hypothèses!$E$39,Hypothèses!$E$38*Hypothèses!$E$40,0)*$G$4 | AN40: =SUM(C40:N40) | AO40: =SUM(O40:Z40) | AP40: =SUM(AA40:AL40)
...

Sheet Synthèse
A1: Synthèse des scénarios
A2: Toutes les valeurs sont calculées à partir des onglets Modèle. Trésorerie hors financement sauf mention contraire.
A4: Indicateur | B4: Unité | C4: Modèle Prudent | D4: Modèle Central | E4: Modèle Ambitieux
A5: Mois de lancement commercial | B5: mois | C5: ='Modèle Prudent'!$B$5 | D5: ='Modèle Central'!$B$5 | E5: ='Modèle Ambitieux'!$B$5
A6: Point bas de trésorerie hors financement | B6: € | C6: =MIN('Modèle Prudent'!C62:AL62) | D6: =MIN('Modèle Central'!C62:AL62) | E6: =MIN('Modèle Ambitieux'!C62:AL62)
A7: Mois du point bas | B7: mois | C7: =MATCH(MIN('Modèle Prudent'!C62:AL62),'Modèle Prudent'!C62:AL62,0) | D7: =MATCH(MIN('Modèle Central'!C62:AL62),'Modèle Central'!C62:AL62,0) | E7: =MATCH(MIN('Modèle Ambitieux'!C62:AL62),'Modèle Ambitieux'!C62:AL62,0)
A8: Besoin de financement (−point bas + réserve) | B8: € | C8: =MAX(0,-MIN('Modèle Prudent'!C62:AL62))+Hypothèses!$C$53 | D8: =MAX(0,-MIN('Modèle Central'!C62:AL62))+Hypothèses!$D$53 | E8: =MAX(0,-MIN('Modèle Ambitieux'!C62:AL62))+Hypothèses!$E$53
A9: Trésorerie cumulée hors financement fin A1 | B9: € | C9: ='Modèle Prudent'!N62 | D9: ='Modèle Central'!N62 | E9: ='Modèle Ambitieux'!N62
A10: Trésorerie cumulée hors financement fin A2 | B10: € | C10: ='Modèle Prudent'!Z62 | D10: ='Modèle Central'!Z62 | E10: ='Modèle Ambitieux'!Z62
